Workbook

Sheet Fig 3
A9: Sheet | B9: Description
A10: REMIND SSP2-RCP2.6 | B10: AESA (FHN allocation) desagregated by fuel type in 2050 with REMIND SSP2-RCP2.6
A11: REMIND SSP1-RCP1.9 | B11: AESA (FHN allocation) desagregated by fuel type in 2050 with REMIND SSP1-RCP1.9
A12: REMIND SSP2-Npi | B12: AESA (FHN allocation) desagregated by fuel type in 2050 with REMIND SSP2-Npi
A13: IMAGE SSP2-RCP2.6 | B13: AESA (FHN allocation) desagregated by fuel type in 2050 with IMAGE SSP2-RCP2.6
A14: REMIND SSP2-RCP2.6 (GDP) | B14: AESA (GDP allocation) desagregated by fuel type in 2050 with REMIND SSP2-RCP2.6
A15: REMIND SSP1-RCP1.9 (GDP) | B15: AESA (GDP allocation) desagregated by fuel type in 2050 with REMIND SSP1-RCP1.9
A16: REMIND SSP2-NPi (GDP) | B16: AESA (GDP allocation) desagregated by fuel type in 2050 with REMIND SSP2-Npi
A17: IMAGE SSP2-RCP2.6 (GDP) | B17: AESA (GDP allocation) desagregated by fuel type in 2050 with IMAGE SSP2-RCP2.6

Sheet REMIND SSP2-RCP2.6
C1: CC | D1: BI | E1: N | F1: P | G1: FWU | H1: SOD | K1: Ratios to baseline
A2: Baseline | B2: fk_historical | C2: 3.3294674 | D2: 125.69077 | E2: 0 | F2: 0 | G2: 0 | H2: 0 | K2: CC | L2: BI | M2: N | N2: P | O2: FWU | P2: SOD
B3: fk | C3: 5.1104606 | D3: 198.12387 | E3: 6.0106438 | F3: 3.1178216 | G3: 0.013691591 | H3: 0.076162895 | J3: Roadmap-70 | K3: =C17/C9 -> 0.9210332 | L3: =D17/D9 -> 1.2820593 | M3: =E17/E9 -> 5.6913816 | N3: =F17/F9 -> 6.6704607 | O3: =G17/G9 -> 5.5296666 | P3: =H17/H9 -> 1.53834
B4: efuels | C4: 0 | D4: 0 | E4: 0 | F4: 0 | G4: 0 | H4: 0 | J4: Roadmap-30-Bio | K4: =C25/C9 -> 0.74249459 | L4: =D25/D9 -> 1.7549149 | M4: =E25/E9 -> 13.297708 | N4: =F25/F9 -> 16.8034 | O4: =G25/G9 -> 12.577169 | P4: =H25/H9 -> 2.5284198
B5: atj | C5: 0 | D5: 0 | E5: 0 | F5: 0 | G5: 0 | H5: 0 | J5: Roadmap-0 | K5: =C33/C9 -> 0.61367522 | L5: =D33/D9 -> 1.54905 | M5: =E33/E9 -> 19.871442 | N5: =F33/F9 -> 16.444805 | O5: =G33/G9 -> 21.126568 | P5: =H33/H9 -> 2.2264249
B6: ft | C6: 0 | D6: 0 | E6: 0 | F6: 0 | G6: 0 | H6: 0 | J6: Roadmap-30-Efuel | K6: =C41/C9 -> 0.77376524 | L6: =D41/D9 -> 1.5228033 | M6: =E41/E9 -> 13.913332 | N6: =F41/F9 -> 13.083277 | O6: =G41/G9 -> 14.581524 | P6: =H41/H9 -> 2.041756
B7: hefa | C7: 0 | D7: 0 | E7: 0 | F7: 0 | G7: 0 | H7: 0 | J7: Bio-Adv | K7: =C49/C9 -> 0.4185382 | L7: =D49/D9 -> 2.1927516 | M7: =E49/E9 -> 16.47049 | N7: =F49/F9 -> 28.027915 | O7: =G49/G9 -> 13.306709 | P7: =H49/H9 -> 3.8150037
B8: lh2 | C8: 0 | D8: 0 | E8: 0 | F8: 0 | G8: 0 | H8: 0 | J8: Bio-HEFA | K8: =C57/C9 -> 0.60776077 | L8: =D57/D9 -> 1.2777372 | M8: =E57/E9 -> 27.888914 | N8: =F57/F9 -> 38.728581 | O8: =G57/G9 -> 15.570348 | P8: =H57/H9 -> 6.3797538
B9: total | C9: =SUM(C2:C8) -> 8.4399281 | D9: =SUM(D2:D8) -> 323.81464 | E9: =SUM(E2:E8) -> 6.0106438 | F9: =SUM(F2:F8) -> 3.1178216 | G9: =SUM(G2:G8) -> 0.013691591 | H9: =SUM(H2:H8) -> 0.076162895 | J9: Efuel-grid | K9: =C65/C9 -> 0.86951773 | L9: =D65/D9 -> 1.2161518 | M9: =E65/E9 -> 22.072827 | N9: =F65/F9 -> 8.166438 | O9: =G65/G9 -> 27.127517 | P9: =H65/H9 -> 1.1330518
A10: Roadmap-70 | B10: fk_historical | C10: =C2 -> 3.3294674 | D10: =D2 -> 125.69077 | E10: 0 | F10: 0 | G10: 0 | H10: 0 | J10: Efuel-RES | K10: =C73/C9 -> 0.70881058 | L10: =D73/D9 -> 1.0646553 | M10: =E73/E9 -> 25.121319 | N10: =F73/F9 -> 11.965255 | O10: =G73/G9 -> 11.730952 | P10: =H73/H9 -> 1.1332429
B11: fk | C11: 4.4779665 | D11: 172.84393 | E11: 4.3889685 | F11: 2.2766314 | G11: 0.0099975915 | H11: 0.0556141 | J11: average over Roadmaps | K11: =AVERAGE(K3:K6) -> 0.76274206 | L11: =AVERAGE(L3:L6) -> 1.5272069 | M11: =AVERAGE(M3:M6) -> 13.193466 | N11: =AVERAGE(N3:N6) -> 13.250486 | O11: =AVERAGE(O3:O6) -> 13.453732 | P11: =AVERAGE(P3:P6) -> 2.0837352
B12: efuels | C12: 0.1830315 | D12: 16.852149 | E12: 11.29685 | F12: 2.1664191 | G12: 0.031628409 | H12: 0.0072893338 | J12: Roadmap-30-Bio vs Roadmap-30-Efuel | K12: =K4/K6-1 -> -0.040413619 | L12: =L4/L6-1 -> 0.15242388 | M12: =M4/M6-1 -> -0.044247091 | N12: =N4/N6-1 -> 0.28434176 | O12: =O4/O6-1 -> -0.13745848 | P12: =P4/P6-1 -> 0.23835554 | Q12: avg over PB other than climate | R12: =AVERAGE(L12:P12) -> 0.098683121
B13: atj | C13: 0.0065808335 | D13: 4.6193884 | E13: 11.064186 | F13: 9.2197212 | G13: 0.022031036 | H13: 0.024180563 | J13: Efuel-grid vs Efuel-RES | K13: =K9/K10-1 -> 0.22672793 | L13: =L9/L10-1 -> 0.14229624 | M13: =M9/M10-1 -> -0.1213508 | N13: =N9/N10-1 -> -0.31748732 | O13: =O9/O10-1 -> 1.3124735 | P13: =P9/P10-1 -> -0.00016865031
B14: ft | C14: -0.23473631 | D14: 94.004925 | E14: 1.7018126 | F14: 3.233471 | G14: 0.0055952365 | H14: 0.013463692 | J14: influence of IAM for Efuel-grid
B15: hefa | C15: 0.011143949 | D15: 1.1384047 | E15: 5.7570507 | F15: 3.9010635 | G15: 0.0064576608 | H15: 0.016616742 | J15: vs REMIND 1-1.9 | K15: ='REMIND SSP1-RCP1.9'!C65/'REMIND SSP2-RCP2.6'!C65 -> 0.84692216 | L15: ='REMIND SSP1-RCP1.9'!D65/'REMIND SSP2-RCP2.6'!D65 -> 1.0677153 | M15: ='REMIND SSP1-RCP1.9'!E65/'REMIND SSP2-RCP2.6'!E65 -> 0.94155871 | N15: ='REMIND SSP1-RCP1.9'!F65/'REMIND SSP2-RCP2.6'!F65 -> 1.0223391 | O15: ='REMIND SSP1-RCP1.9'!G65/'REMIND SSP2-RCP2.6'!G65 -> 1.7941038 | P15: ='REMIND SSP1-RCP1.9'!H65/'REMIND SSP2-RCP2.6'!H65 -> 1.0157244
B16: lh2 | C16: 0 | D16: 0 | E16: 0 | F16: 0 | G16: 0 | H16: 0 | J16: vs REMIND 2-Npi | K16: ='REMIND SSP2-NPi'!C65/'REMIND SSP2-RCP2.6'!C65 -> 2.3830026 | L16: ='REMIND SSP2-NPi'!D65/'REMIND SSP2-RCP2.6'!D65 -> 1.9928606 | M16: ='REMIND SSP2-NPi'!E65/'REMIND SSP2-RCP2.6'!E65 -> 0.81833196 | N16: ='REMIND SSP2-NPi'!F65/'REMIND SSP2-RCP2.6'!F65 -> 0.84482801 | O16: ='REMIND SSP2-NPi'!G65/'REMIND SSP2-RCP2.6'!G65 -> 1.4105102 | P16: ='REMIND SSP2-NPi'!H65/'REMIND SSP2-RCP2.6'!H65 -> 1.421843
B17: total | C17: =SUM(C10:C16) -> 7.7734539 | D17: =SUM(D10:D16) -> 415.14957 | E17: =SUM(E10:E16) -> 34.208867 | F17: =SUM(F10:F16) -> 20.797306 | G17: =SUM(G10:G16) -> 0.075709934 | H17: =SUM(H10:H16) -> 0.11716443 | J17: vs IMAGE 2-2.6 | K17: ='IMAGE SSP2-RCP2.6'!C65/'REMIND SSP2-RCP2.6'!C65 -> 1.5381736 | L17: ='IMAGE SSP2-RCP2.6'!D65/'REMIND SSP2-RCP2.6'!D65 -> 1.6244498 | M17: ='IMAGE SSP2-RCP2.6'!E65/'REMIND SSP2-RCP2.6'!E65 -> 0.79865602 | N17: ='IMAGE SSP2-RCP2.6'!F65/'REMIND SSP2-RCP2.6'!F65 -> 0.93963233 | O17: ='IMAGE SSP2-RCP2.6'!G65/'REMIND SSP2-RCP2.6'!G65 -> 7.6845447 | P17: ='IMAGE SSP2-RCP2.6'!H65/'REMIND SSP2-RCP2.6'!H65 -> 2.1419109
A18: Roadmap-30-Bio | B18: fk_historical | C18: =C10 -> 3.3294674 | D18: =D10 -> 125.69077 | E18: 0 | F18: 0 | G18: 0 | H18: 0 | J18: avg | K18: =AVERAGE(K15:K17) -> 1.5893661 | L18: =AVERAGE(L15:L17) -> 1.5616752 | M18: =AVERAGE(M15:M17) -> 0.8528489 | N18: =AVERAGE(N15:N17) -> 0.93559982 | O18: =AVERAGE(O15:O17) -> 3.6297196 | P18: =AVERAGE(P15:P17) -> 1.5264927 | Q18: =AVERAGE(K18:P18) -> 1.6826171
B19: fk | C19: 3.106952 | D19: 118.75352 | E19: 1.6913894 | F19: 0.87735201 | G19: 0.0038528007 | H19: 0.021432166 | J19: influence of IAM for Efuel-RES
B20: efuels | C20: 0.63197852 | D20: 46.223365 | E20: 25.412066 | F20: 4.8733221 | G20: 0.071147554 | H20: 0.016397229 | J20: vs REMIND 1-1.9 | K20: ='REMIND SSP1-RCP1.9'!C73/'REMIND SSP2-RCP2.6'!C73 -> 0.95076219 | L20: ='REMIND SSP1-RCP1.9'!D73/'REMIND SSP2-RCP2.6'!D73 -> 0.99652036 | M20: ='REMIND SSP1-RCP1.9'!E73/'REMIND SSP2-RCP2.6'!E73 -> 0.92603507 | N20: ='REMIND SSP1-RCP1.9'!F73/'REMIND SSP2-RCP2.6'!F73 -> 0.93878191 | O20: ='REMIND SSP1-RCP1.9'!G73/'REMIND SSP2-RCP2.6'!G73 -> 1.1563957 | P20: ='REMIND SSP1-RCP1.9'!H73/'REMIND SSP2-RCP2.6'!H73 -> 1.0181345
B21: atj | C21: 0.027361268 | D21: 13.498076 | E21: 31.553022 | F21: 26.292948 | G21: 0.06282846 | H21: 0.068958515 | J21: vs REMIND 2-Npi | K21: ='REMIND SSP2-NPi'!C73/'REMIND SSP2-RCP2.6'!C73 -> 0.95055348 | L21: ='REMIND SSP2-NPi'!D73/'REMIND SSP2-RCP2.6'!D73 -> 0.96469224 | M21: ='REMIND SSP2-NPi'!E73/'REMIND SSP2-RCP2.6'!E73 -> 0.69532762 | N21: ='REMIND SSP2-NPi'!F73/'REMIND SSP2-RCP2.6'!F73 -> 0.92285895 | O21: ='REMIND SSP2-NPi'!G73/'REMIND SSP2-RCP2.6'!G73 -> 0.99602545 | P21: ='REMIND SSP2-NPi'!H73/'REMIND SSP2-RCP2.6'!H73 -> 1.0057335
B22: ft | C22: -0.87115375 | D22: 260.46927 | E22: 4.8532563 | F22: 9.2212642 | G22: 0.015956585 | H22: 0.038395971 | J22: vs IMAGE 2-2.6 | K22: ='IMAGE SSP2-RCP2.6'!C73/'REMIND SSP2-RCP2.6'!C73 -> 0.86276713 | L22: ='IMAGE SSP2-RCP2.6'!D73/'REMIND SSP2-RCP2.6'!D73 -> 0.91228593 | M22: ='IMAGE SSP2-RCP2.6'!E73/'REMIND SSP2-RCP2.6'!E73 -> 0.90477366 | N22: ='IMAGE SSP2-RCP2.6'!F73/'REMIND SSP2-RCP2.6'!F73 -> 0.89794532 | O22: ='IMAGE SSP2-RCP2.6'!G73/'REMIND SSP2-RCP2.6'!G73 -> 1.4755115 | P22: ='IMAGE SSP2-RCP2.6'!H73/'REMIND SSP2-RCP2.6'!H73 -> 0.75637968
B23: hefa | C23: 0.041995468 | D23: 3.6321464 | E23: 16.418049 | F23: 11.125115 | G23: 0.01841606 | H23: 0.047387891 | J23: avg | K23: =AVERAGE(K20:K22) -> 0.92136093 | L23: =AVERAGE(L20:L22) -> 0.95783284 | M23: =AVERAGE(M20:M22) -> 0.84204545 | N23: =AVERAGE(N20:N22) -> 0.91986206 | O23: =AVERAGE(O20:O22) -> 1.2093109 | P23: =AVERAGE(P20:P22) -> 0.92674922 | Q23: =AVERAGE(K23:P23) -> 0.96286023
B24: lh2 | C24: 0 | D24: 0 | E24: 0 | F24: 0 | G24: 0 | H24: 0
B25: total | C25: =SUM(C18:C24) -> 6.2666009 | D25: =SUM(D18:D24) -> 568.26715 | E25: =SUM(E18:E24) -> 79.927783 | F25: =SUM(F18:F24) -> 52.390001 | G25: =SUM(G18:G24) -> 0.17220146 | H25: =SUM(H18:H24) -> 0.19257177
A26: Roadmap-0 | B26: fk_historical | C26: =C18 -> 3.3294674 | D26: =D18 -> 125.69077 | E26: 0 | F26: 0 | G26: 0 | H26: 0
B27: fk | C27: 1.7826838 | D27: 67.298122 | E27: 0 | F27: 0 | G27: 0 | H27: 0
B28: efuels | C28: 1.1128906 | D28: 107.01907 | E28: 73.861191 | F28: 14.164506 | G28: 0.20679322 | H28: 0.047659206
B29: atj | C29: 0.044029488 | D29: 11.326403 | E29: 24.463075 | F29: 20.384937 | G29: 0.048710939 | H29: 0.053463574
B30: ft | C30: -1.1622769 | D30: 183.56209 | E30: 3.7627323 | F30: 7.1492511 | G30: 0.012371149 | H30: 0.029768417
B31: hefa | C31: 0.057662257 | D31: 3.7636744 | E31: 12.728922 | F31: 8.6253077 | G31: 0.014277981 | H31: 0.036739857
B32: lh2 | C32: 0.014917969 | D32: 2.9449141 | E32: 4.6242385 | F32: 0.94796574 | G32: 0.0071030418 | H32: 0.001939909
B33: total | C33: =SUM(C26:C32) -> 5.1793747 | D33: =SUM(D26:D32) -> 501.60505 | E33: =SUM(E26:E32) -> 119.44016 | F33: =SUM(F26:F32) -> 51.271968 | G33: =SUM(G26:G32) -> 0.28925634 | H33: =SUM(H26:H32) -> 0.16957096
A34: Roadmap-30-Efuel | B34: fk_historical | C34: =C26 -> 3.3294674 | D34: =D26 -> 125.69077 | E34: 0 | F34: 0 | G34: 0 | H34: 0
B35: fk | C35: 3.4631906 | D35: 132.2986 | E35: 1.8031931 | F35: 0.93534647 | G35: 0.0041074773 | H35: 0.022848868
B36: efuels | C36: 0.3368721 | D36: 53.961275 | E36: 46.862083 | F36: 8.9868342 | G36: 0.13120234 | H36: 0.030237932
B37: atj | C37: 0.023349056 | D37: 9.1317585 | E37: 20.88398 | F37: 17.402498 | G37: 0.041584236 | H37: 0.045641531
B38: ft | C38: -0.6544998 | D38: 169.45547 | E38: 3.2122219 | F38: 6.1032726 | G38: 0.010561175 | H38: 0.025413118
B39: hefa | C39: 0.032143547 | D39: 2.5681492 | E39: 10.866604 | F39: 7.3633733 | G39: 0.012189027 | H39: 0.031364595
B40: lh2 | C40: 0 | D40: 0 | E40: 0 | F40: 0 | G40: 0 | H40: 0
...

Sheet REMIND SSP1-RCP1.9
C1: CC | D1: BI | E1: N | F1: P | G1: FWU | H1: SOD | K1: Ratios to baseline
A2: Baseline | B2: fk_historical | C2: 3.3294674 | D2: 125.69077 | E2: 0 | F2: 0 | G2: 0 | H2: 0 | K2: CC | L2: BI | M2: N | N2: P | O2: SOD | P2: FWU
B3: fk | C3: 5.0927028 | D3: 201.29909 | E3: 5.1868003 | F3: 3.1075475 | G3: 0.0231499 | H3: 0.076671773 | J3: Roadmap-70 | K3: =C17/C9 -> 0.93858639 | L3: =D17/D9 -> 1.603028 | M3: =E17/E9 -> 4.7419332 | N3: =F17/F9 -> 4.8630225 | O3: =G17/G9 -> 4.9213427 | P3: =H17/H9 -> 1.409048
B4: efuels | C4: 0 | D4: 0 | E4: 0 | F4: 0 | G4: 0 | H4: 0 | J4: Roadmap-30-Bio | K4: =C25/C9 -> 0.81935946 | L4: =D25/D9 -> 2.6858642 | M4: =E25/E9 -> 10.486867 | N4: =F25/F9 -> 11.638142 | O4: =G25/G9 -> 10.757309 | P4: =H25/H9 -> 2.1591803
B5: atj | C5: 0 | D5: 0 | E5: 0 | F5: 0 | G5: 0 | H5: 0 | J5: Roadmap-0 | K5: =C33/C9 -> 0.69798199 | L5: =D33/D9 -> 2.3912899 | M5: =E33/E9 -> 18.553218 | N5: =F33/F9 -> 12.547109 | O5: =G33/G9 -> 20.487546 | P5: =H33/H9 -> 1.9477611
B6: ft | C6: 0 | D6: 0 | E6: 0 | F6: 0 | G6: 0 | H6: 0 | J6: Roadmap-30-Efuel | K6: =C41/C9 -> 0.82893611 | L6: =D41/D9 -> 2.1916883 | M6: =E41/E9 -> 12.508513 | N6: =F41/F9 -> 9.7121324 | O6: =G41/G9 -> 13.752444 | P6: =H41/H9 -> 1.7996734
B7: hefa | C7: 0 | D7: 0 | E7: 0 | F7: 0 | G7: 0 | H7: 0 | J7: Bio-Adv | K7: =C49/C9 -> 0.64814549 | L7: =D49/D9 -> 3.9450515 | M7: =E49/E9 -> 10.483932 | N7: =F49/F9 -> 18.27791 | O7: =G49/G9 -> 9.3032742 | P7: =H49/H9 -> 3.1197584
B8: lh2 | C8: 0 | D8: 0 | E8: 0 | F8: 0 | G8: 0 | H8: 0 | J8: Bio-HEFA | K8: =C57/C9 -> 0.66668641 | L8: =D57/D9 -> 1.9524172 | M8: =E57/E9 -> 29.56417 | N8: =F57/F9 -> 35.879314 | O8: =G57/G9 -> 12.489679 | P8: =H57/H9 -> 6.1275821
B9: total | C9: 8.1869412 | D9: 318.10973 | E9: 5.1868003 | F9: 3.1075475 | G9: 0.0231499 | H9: 0.076671773 | J9: Efuel-grid | K9: =C65/C9 -> 0.75916995 | L9: =D65/D9 -> 1.3217909 | M9: =E65/E9 -> 24.083901 | N9: =F65/F9 -> 8.3764718 | O9: =G65/G9 -> 28.784747 | P9: =H65/H9 -> 1.1432299
A10: Roadmap-70 | B10: fk_historical | C10: 3.3294674 | D10: 125.69077 | E10: 0 | F10: 0 | G10: 0 | H10: 0 | J10: Efuel-RES | K10: =C73/C9 -> 0.69473498 | L10: =D73/D9 -> 1.0799776 | M10: =E73/E9 -> 26.958228 | N10: =F73/F9 -> 11.269902 | O10: =G73/G9 -> 8.023143 | P10: =H73/H9 -> 1.1461358
B11: fk | C11: 4.4630218 | D11: 175.08781 | E11: 3.7873985 | F11: 2.2691293 | G11: 0.016904043 | H11: 0.055985682
B12: efuels | C12: 0.10708512 | D12: 19.866235 | E12: 10.637031 | F12: 2.21488 | G12: 0.056745797 | H12: 0.0074045135
B13: atj | C13: 0.25463947 | D13: 97.681165 | E13: 2.3117944 | F13: 3.0867593 | G13: 0.01336794 | H13: 0.01387115
B14: ft | C14: -0.24197943 | D14: 98.367778 | E14: 2.0385405 | F14: 3.5732678 | G14: 0.017667642 | H14: 0.01406769
B15: hefa | C15: 0.0071462446 | D15: 2.1251721 | E15: 5.8206963 | F15: 3.968037 | G15: 0.0092431696 | H15: 0.016705169
B16: lh2 | C16: 0 | D16: 0 | E16: 0 | F16: 0 | G16: 0 | H16: 0
B17: total | C17: 7.6841516 | D17: 509.9388 | E17: 24.595461 | F17: 15.112073 | G17: 0.11392859 | H17: 0.1080342
A18: Roadmap-30-Bio | B18: fk_historical | C18: 3.3294674 | D18: 125.69077 | E18: 0 | F18: 0 | G18: 0 | H18: 0
B19: fk | C19: 3.0977299 | D19: 119.48753 | E19: 1.4595607 | F19: 0.87446091 | G19: 0.0065143598 | H19: 0.021575364
B20: efuels | C20: 0.43389859 | D20: 51.975166 | E20: 23.927816 | F20: 4.9823339 | G20: 0.12764868 | H20: 0.016656324
B21: atj | C21: 0.95094515 | D21: 287.05363 | E21: 6.5928122 | F21: 8.8028695 | G21: 0.038122906 | H21: 0.039557968
B22: ft | C22: -0.8962772 | D22: 272.74267 | E22: 5.8135422 | F22: 10.190302 | G22: 0.050384862 | H22: 0.040118462
B23: hefa | C23: 0.027512883 | D23: 6.3298817 | E23: 16.599555 | F23: 11.316111 | G23: 0.026359818 | H23: 0.047640067
B24: lh2 | C24: 0 | D24: 0 | E24: 0 | F24: 0 | G24: 0 | H24: 0
B25: total | C25: 6.7080477 | D25: 854.39952 | E25: 54.393286 | F25: 36.166078 | G25: 0.24903063 | H25: 0.16554818
A26: Roadmap-0 | B26: fk_historical | C26: 3.3294674 | D26: 125.69077 | E26: 0 | F26: 0 | G26: 0 | H26: 0
B27: fk | C27: 1.7788972 | D27: 67.155174 | E27: 0 | F27: 0 | G27: 0 | H27: 0
B28: efuels | C28: 0.70238089 | D28: 129.97404 | E28: 69.547159 | F28: 14.481354 | G28: 0.37101602 | H28: 0.048412275
B29: atj | C29: 1.2858864 | D29: 243.26373 | E29: 5.1114108 | F29: 6.8248695 | G29: 0.029556709 | H29: 0.030669314
B30: ft | C30: -1.1922886 | D30: 192.68002 | E30: 4.5072424 | F30: 7.9005468 | G30: 0.039063411 | H30: 0.031103865
B31: hefa | C31: 0.039163898 | D31: 5.58078 | E31: 12.869644 | F31: 8.7733871 | G31: 0.020436782 | H31: 0.03693537
B32: lh2 | C32: 0.0060592361 | D32: 5.2281908 | E32: 4.1963826 | F32: 1.0105787 | G32: 0.014211713 | H32: 0.0022174706
B33: total | C33: 5.7143375 | D33: 760.69258 | E33: 96.231838 | F33: 38.990736 | G33: 0.47428464 | H33: 0.14933829
A34: Roadmap-30-Efuel | B34: fk_historical | C34: 3.3294674 | D34: 125.69077 | E34: 0 | F34: 0 | G34: 0 | H34: 0
B35: fk | C35: 3.452693 | D35: 133.05598 | E35: 1.5560401 | F35: 0.93226425 | G35: 0.00694497 | H35: 0.023001532
B36: efuels | C36: 0.16948682 | D36: 72.038706 | E36: 44.124996 | F36: 9.1878616 | G36: 0.23539539 | H36: 0.030715725
B37: atj | C37: 0.72106893 | D37: 193.45255 | E37: 4.3635806 | F37: 5.82635 | G37: 0.025232385 | H37: 0.026182208
B38: ft | C38: -0.67260576 | D38: 177.52308 | E38: 3.8478057 | F38: 6.7446492 | G38: 0.033348199 | H38: 0.026553183
B39: hefa | C39: 0.021569814 | D39: 4.3163938 | E39: 10.986737 | F39: 7.4897878 | G39: 0.017446757 | H39: 0.031531503
B40: lh2 | C40: 0 | D40: 0 | E40: 0 | F40: 0 | G40: 0 | H40: 0
...

Sheet REMIND SSP2-NPi
C1: CC | D1: BI | E1: N | F1: P | G1: FWU | H1: SOD | K1: Ratios to baseline
A2: Baseline | B2: fk_historical | C2: 3.3294674 | D2: 125.69077 | E2: 0 | F2: 0 | G2: 0 | H2: 0 | K2: CC | L2: BI | M2: N | N2: P | O2: SOD | P2: FWU
B3: fk | C3: 5.1296525 | D3: 198.35218 | E3: 4.9253321 | F3: 2.7827474 | G3: 0.01173039 | H3: 0.076022866 | J3: Roadmap-70 | K3: 0.9 | L3: 1.2 | M3: 5.7 | N3: 6.7 | O3: 5.5 | P3: 1.5
B4: efuels | C4: 0 | D4: 0 | E4: 0 | F4: 0 | G4: 0 | H4: 0 | J4: Roadmap-30-Bio | K4: 0.8 | L4: 1.7 | M4: 13.3 | N4: 16.8 | O4: 12.6 | P4: 2.5
B5: atj | C5: 0 | D5: 0 | E5: 0 | F5: 0 | G5: 0 | H5: 0 | J5: Roadmap-0 | K5: 0.7 | L5: 1.5 | M5: 19.9 | N5: 16.4 | O5: 21.1 | P5: 2.2
B6: ft | C6: 0 | D6: 0 | E6: 0 | F6: 0 | G6: 0 | H6: 0 | J6: Roadmap-30-Efuel | K6: 0.8 | L6: 1.5 | M6: 13.9 | N6: 13.1 | O6: 14.6 | P6: 2
B7: hefa | C7: 0 | D7: 0 | E7: 0 | F7: 0 | G7: 0 | H7: 0 | J7: Bio-Adv | K7: 0.5 | L7: 2 | M7: 16.5 | N7: 28 | O7: 13.3 | P7: 3.8
B8: lh2 | C8: 0 | D8: 0 | E8: 0 | F8: 0 | G8: 0 | H8: 0 | J8: Bio-HEFA | K8: 0.7 | L8: 1.2 | M8: 27.9 | N8: 38.7 | O8: 15.6 | P8: 6.4
B9: total | C9: 8.223891 | D9: 315.16282 | E9: 4.9253321 | F9: 2.7827474 | G9: 0.01173039 | H9: 0.076022866 | J9: Efuel-grid | K9: 0.9 | L9: 1.2 | M9: 22.1 | N9: 8.2 | O9: 27.1 | P9: 1.1
A10: Roadmap-70 | B10: fk_historical | C10: 3.3294674 | D10: 125.69077 | E10: 0 | F10: 0 | G10: 0 | H10: 0 | J10: Efuel-RES | K10: 0.7 | L10: 1.1 | M10: 25.1 | N10: 12 | O10: 11.7 | P10: 1.1
B11: fk | C11: 4.4941071 | D11: 173.09093 | E11: 3.5964745 | F11: 2.0319605 | G11: 0.0085655236 | H11: 0.055511851
B12: efuels | C12: 1.0965554 | D12: 52.007391 | E12: 9.2445676 | F12: 1.8301307 | G12: 0.044618353 | H12: 0.010390507
B13: atj | C13: 0.28084985 | D13: 60.787819 | E13: 1.9508219 | F13: 1.9226759 | G13: 0.0067054394 | H13: 0.013723122
B14: ft | C14: -0.22991061 | D14: 93.719864 | E14: 1.5321485 | F14: 3.1418158 | G14: 0.0031496936 | H14: 0.01328539
B15: hefa | C15: 0.013180163 | D15: 1.0874994 | E15: 5.7141735 | F15: 3.8863152 | G15: 0.0064795847 | H15: 0.016597932
B16: lh2 | C16: 0 | D16: 0 | E16: 0 | F16: 0 | G16: 0 | H16: 0
B17: total | C17: 8.7490204 | D17: 497.50415 | E17: 22.038186 | F17: 12.812898 | G17: 0.069518594 | H17: 0.1095088
A18: Roadmap-30-Bio | B18: fk_historical | C18: 3.3294674 | D18: 125.69077 | E18: 0 | F18: 0 | G18: 0 | H18: 0
B19: fk | C19: 3.1168182 | D19: 118.98636 | E19: 1.3859838 | F19: 0.78306247 | G19: 0.0033009205 | H19: 0.021392762
B20: efuels | C20: 2.8180489 | D20: 130.25416 | E20: 20.795494 | F20: 4.1168472 | G20: 0.10036821 | H20: 0.023373265
B21: atj | C21: 1.0476072 | D21: 182.66791 | E21: 5.5633849 | F21: 5.4831177 | G21: 0.019122679 | H21: 0.039135818
B22: ft | C22: -0.85354408 | D22: 259.80158 | E22: 4.3694055 | F22: 8.9598804 | G22: 0.0089823463 | H22: 0.037887487
B23: hefa | C23: 0.04942436 | D23: 3.5482053 | E23: 16.295771 | F23: 11.083056 | G23: 0.018478583 | H23: 0.047334248
B24: lh2 | C24: 0 | D24: 0 | E24: 0 | F24: 0 | G24: 0 | H24: 0
B25: total | C25: 9.272593 | D25: 812.06885 | E25: 48.410039 | F25: 30.425963 | G25: 0.15025274 | H25: 0.16912358
A26: Roadmap-0 | B26: fk_historical | C26: 3.3294674 | D26: 125.69077 | E26: 0 | F26: 0 | G26: 0 | H26: 0
B27: fk | C27: 1.7864013 | D27: 67.438459 | E27: 0 | F27: 0 | G27: 0 | H27: 0
B28: efuels | C28: 5.9430284 | D28: 293.73435 | E28: 60.442938 | F28: 11.965782 | G28: 0.29172423 | H28: 0.067935333
B29: atj | C29: 1.413297 | D29: 164.31415 | E29: 4.3132954 | F29: 4.2510641 | G29: 0.014825823 | H29: 0.030342021
B30: ft | C30: -1.1394847 | D30: 183.38946 | E30: 3.3876024 | F30: 6.9466001 | G30: 0.006964018 | H30: 0.029374189
B31: hefa | C31: 0.067265047 | D31: 3.8436782 | E31: 12.63412 | F31: 8.5926991 | G31: 0.014326455 | H31: 0.036698268
B32: lh2 | C32: 0.033540295 | D32: 4.3378608 | E32: 7.2616 | F32: 14.976897 | G32: 0.0080559913 | H32: 0.0021829497
B33: total | C33: 11.198286 | D33: 833.86859 | E33: 88.039556 | F33: 46.733042 | G33: 0.33589652 | H33: 0.16653276
A34: Roadmap-30-Efuel | B34: fk_historical | C34: 3.3294674 | D34: 125.69077 | E34: 0 | F34: 0 | G34: 0 | H34: 0
B35: fk | C35: 3.474519 | D35: 132.5774 | E35: 1.4775996 | F35: 0.83482422 | G35: 0.003519117 | H35: 0.02280686
B36: efuels | C36: 2.4441106 | D36: 136.28596 | E36: 38.348718 | F36: 7.591828 | G36: 0.18508779 | H36: 0.043102354
B37: atj | C37: 0.79294934 | D37: 124.66118 | E37: 3.6822343 | F37: 3.6291078 | G37: 0.012656716 | H37: 0.025902801
B38: ft | C38: -0.64153466 | D38: 169.06299 | E38: 2.8919758 | F38: 5.9302707 | G38: 0.0059451402 | H38: 0.025076569
B39: hefa | C39: 0.037598772 | D39: 2.5329113 | E39: 10.785672 | F39: 7.3355355 | G39: 0.012230409 | H39: 0.031329091
B40: lh2 | C40: 0 | D40: 0 | E40: 0 | F40: 0 | G40: 0 | H40: 0
...

Sheet IMAGE SSP2-RCP2.6
C1: CC | D1: BI | E1: N | F1: P | G1: FWU | H1: SOD | K1: Ratios to baseline
A2: Baseline | B2: fk_historical | C2: 3.3294674 | D2: 125.69077 | E2: 0 | F2: 0 | G2: 0 | H2: 0 | K2: CC | L2: BI | M2: N | N2: P | O2: SOD | P2: FWU
B3: fk | C3: 5.1324018 | D3: 198.3431 | E3: 4.3134701 | F3: 2.5152353 | G3: 0.018982308 | H3: 0.075409853 | J3: Roadmap-70 | K3: 0.9 | L3: 1.2 | M3: 5.7 | N3: 6.7 | O3: 5.5 | P3: 1.5
B4: efuels | C4: 0 | D4: 0 | E4: 0 | F4: 0 | G4: 0 | H4: 0 | J4: Roadmap-30-Bio | K4: 0.8 | L4: 1.7 | M4: 13.3 | N4: 16.8 | O4: 12.6 | P4: 2.5
B5: atj | C5: 0 | D5: 0 | E5: 0 | F5: 0 | G5: 0 | H5: 0 | J5: Roadmap-0 | K5: 0.7 | L5: 1.5 | M5: 19.9 | N5: 16.4 | O5: 21.1 | P5: 2.2
B6: ft | C6: 0 | D6: 0 | E6: 0 | F6: 0 | G6: 0 | H6: 0 | J6: Roadmap-30-Efuel | K6: 0.8 | L6: 1.5 | M6: 13.9 | N6: 13.1 | O6: 14.6 | P6: 2
B7: hefa | C7: 0 | D7: 0 | E7: 0 | F7: 0 | G7: 0 | H7: 0 | J7: Bio-Adv | K7: 0.5 | L7: 2 | M7: 16.5 | N7: 28 | O7: 13.3 | P7: 3.8
B8: lh2 | C8: 0 | D8: 0 | E8: 0 | F8: 0 | G8: 0 | H8: 0 | J8: Bio-HEFA | K8: 0.7 | L8: 1.2 | M8: 27.9 | N8: 38.7 | O8: 15.6 | P8: 6.4
B9: total | C9: 8.2266402 | D9: 315.15374 | E9: 4.3134701 | F9: 2.5152353 | G9: 0.018982308 | H9: 0.075409853 | J9: Efuel-grid | K9: 0.9 | L9: 1.2 | M9: 22.1 | N9: 8.2 | O9: 27.1 | P9: 1.1
A10: Roadmap-70 | B10: fk_historical | C10: 3.3294674 | D10: 125.69077 | E10: 0 | F10: 0 | G10: 0 | H10: 0 | J10: Efuel-RES | K10: 0.7 | L10: 1.1 | M10: 25.1 | N10: 12 | O10: 11.7 | P10: 1.1
B11: fk | C11: 4.4970097 | D11: 173.11809 | E11: 3.1496933 | F11: 1.8366233 | G11: 0.01386087 | H11: 0.055064229
B12: efuels | C12: 0.54986132 | D12: 38.948207 | E12: 9.0226926 | F12: 2.0359741 | G12: 0.24311998 | H12: 0.015684381
B13: atj | C13: 0.28250493 | D13: 81.647989 | E13: 1.7869447 | F13: 2.4022544 | G13: 0.024195058 | H13: 0.013896473
B14: ft | C14: -0.22493286 | D14: 94.047427 | E14: 1.3087728 | F14: 2.9948027 | G14: 0.0053309689 | H14: 0.012657986
B15: hefa | C15: 0.012872911 | D15: 1.2298328 | E15: 5.6056962 | F15: 3.8580548 | G15: 0.0080860654 | H15: 0.016543759
B16: lh2 | C16: 0 | D16: 0 | E16: 0 | F16: 0 | G16: 0 | H16: 0
B17: total | C17: 8.2115544 | D17: 505.80219 | E17: 20.8738 | F17: 13.127709 | G17: 0.29459295 | H17: 0.11384683
A18: Roadmap-30-Bio | B18: fk_historical | C18: 3.3294674 | D18: 125.69077 | E18: 0 | F18: 0 | G18: 0 | H18: 0
B19: fk | C19: 3.1195815 | D19: 119.05891 | E19: 1.2138064 | F19: 0.70778481 | G19: 0.0053416032 | H19: 0.021220261
B20: efuels | C20: 1.551345 | D20: 99.483801 | E20: 20.29639 | F20: 4.5798883 | G20: 0.54689417 | H20: 0.035281743
B21: atj | C21: 1.0569521 | D21: 242.33187 | E21: 5.0960374 | F21: 6.8507873 | G21: 0.068999853 | H21: 0.039630183
B22: ft | C22: -0.83384609 | D22: 260.94345 | E22: 3.7323792 | F22: 8.5406262 | G22: 0.015202942 | H22: 0.036098247
B23: hefa | C23: 0.048752145 | D23: 3.9618157 | E23: 15.986414 | F23: 11.002462 | G23: 0.02305997 | H23: 0.047179757
B24: lh2 | C24: 0 | D24: 0 | E24: 0 | F24: 0 | G24: 0 | H24: 0
B25: total | C25: 8.0370231 | D25: 842.59049 | E25: 46.325026 | F25: 31.681549 | G25: 0.65949854 | H25: 0.17941019
A26: Roadmap-0 | B26: fk_historical | C26: 3.3294674 | D26: 125.69077 | E26: 0 | F26: 0 | G26: 0 | H26: 0
B27: fk | C27: 1.788833 | D27: 67.530259 | E27: 0 | F27: 0 | G27: 0 | H27: 0
B28: efuels | C28: 3.031851 | D28: 233.38803 | E28: 58.992272 | F28: 13.31163 | G28: 1.5895699 | H28: 0.1025478
B29: atj | C29: 1.4329236 | D29: 211.03907 | E29: 3.9509605 | F29: 5.3114191 | G29: 0.053495623 | H29: 0.030725303
B30: ft | C30: -1.110745 | D30: 184.78317 | E30: 2.8937156 | F30: 6.6215521 | G30: 0.011786849 | H30: 0.027986991
B31: hefa | C31: 0.067466613 | D31: 4.1916345 | E31: 12.394275 | F31: 8.530215 | G31: 0.017878407 | H31: 0.036578491
B32: lh2 | C32: 0.058718753 | D32: 5.6580558 | E32: 7.363106 | F32: 15.029947 | G32: 0.070040465 | H32: 0.0050618189
B33: total | C33: 8.3632864 | D33: 823.40086 | E33: 85.59433 | F33: 48.804763 | G33: 1.7427712 | H33: 0.20290041
A34: Roadmap-30-Efuel | B34: fk_historical | C34: 3.3294674 | D34: 125.69077 | E34: 0 | F34: 0 | G34: 0 | H34: 0
B35: fk | C35: 3.4774431 | D35: 132.65392 | E35: 1.294041 | F35: 0.75457058 | G35: 0.0056946923 | H35: 0.022622956
B36: efuels | C36: 1.1234836 | D36: 117.87079 | E36: 37.428326 | F36: 8.4457166 | G36: 1.0085209 | H36: 0.065062634
B37: atj | C37: 0.80240165 | D37: 164.27427 | E37: 3.3729112 | F37: 4.5343265 | G37: 0.045668892 | H37: 0.026230006
B38: ft | C38: -0.62615162 | D38: 169.90731 | E38: 2.4703476 | F38: 5.6527791 | G38: 0.010062362 | H38: 0.023892325
B39: hefa | C39: 0.037507118 | D39: 2.8200035 | E39: 10.580918 | F39: 7.2821932 | G39: 0.015262689 | H39: 0.031226837
B40: lh2 | C40: 0 | D40: 0 | E40: 0 | F40: 0 | G40: 0 | H40: 0
...

Sheet REMIND SSP2-RCP2.6 (GDP)
C1: CC | D1: BI | E1: N | F1: P | G1: SOD | H1: FWU | K1: Ratios to baseline
A2: Baseline | B2: fk_historical | C2: ='REMIND SSP2-RCP2.6'!C2/'REMIND SSP2-RCP2.6 (GDP)'!K$14*'REMIND SSP2-RCP2.6 (GDP)'!K$13 -> 1.033283 | D2: ='REMIND SSP2-RCP2.6'!D2/'REMIND SSP2-RCP2.6 (GDP)'!L$14*'REMIND SSP2-RCP2.6 (GDP)'!L$13 -> 0.52009974 | E2: ='REMIND SSP2-RCP2.6'!E2/'REMIND SSP2-RCP2.6 (GDP)'!M$14*'REMIND SSP2-RCP2.6 (GDP)'!M$13 -> 0 | F2: ='REMIND SSP2-RCP2.6'!F2/'REMIND SSP2-RCP2.6 (GDP)'!N$14*'REMIND SSP2-RCP2.6 (GDP)'!N$13 -> 0 | G2: ='REMIND SSP2-RCP2.6'!G2/'REMIND SSP2-RCP2.6 (GDP)'!O$14*'REMIND SSP2-RCP2.6 (GDP)'!O$13 -> 0 | H2: ='REMIND SSP2-RCP2.6'!H2/'REMIND SSP2-RCP2.6 (GDP)'!P$14*'REMIND SSP2-RCP2.6 (GDP)'!P$13 -> 0 | K2: CC | L2: BI | M2: N | N2: P | O2: SOD | P2: FWU
B3: fk | C3: ='REMIND SSP2-RCP2.6'!C3/'REMIND SSP2-RCP2.6 (GDP)'!K$14*'REMIND SSP2-RCP2.6 (GDP)'!K$13 -> 1.586005 | D3: ='REMIND SSP2-RCP2.6'!D3/'REMIND SSP2-RCP2.6 (GDP)'!L$14*'REMIND SSP2-RCP2.6 (GDP)'!L$13 -> 0.8198229 | E3: ='REMIND SSP2-RCP2.6'!E3/'REMIND SSP2-RCP2.6 (GDP)'!M$14*'REMIND SSP2-RCP2.6 (GDP)'!M$13 -> 0.041452716 | F3: ='REMIND SSP2-RCP2.6'!F3/'REMIND SSP2-RCP2.6 (GDP)'!N$14*'REMIND SSP2-RCP2.6 (GDP)'!N$13 -> 0.0021502218 | G3: ='REMIND SSP2-RCP2.6'!G3/'REMIND SSP2-RCP2.6 (GDP)'!O$14*'REMIND SSP2-RCP2.6 (GDP)'!O$13 -> 0.010386724 | H3: ='REMIND SSP2-RCP2.6'!H3/'REMIND SSP2-RCP2.6 (GDP)'!P$14*'REMIND SSP2-RCP2.6 (GDP)'!P$13 -> 0.010505227 | J3: Roadmap-70 | K3: =C17/C9 -> 0.9210332 | L3: =D17/D9 -> 1.2820593 | M3: =E17/E9 -> 5.6913816 | N3: =F17/F9 -> 6.6704607 | O3: =G17/G9 -> 5.5296666 | P3: =H17/H9 -> 1.53834
B4: efuels | C4: ='REMIND SSP2-RCP2.6'!C4/'REMIND SSP2-RCP2.6 (GDP)'!K$14*'REMIND SSP2-RCP2.6 (GDP)'!K$13 -> 0 | D4: ='REMIND SSP2-RCP2.6'!D4/'REMIND SSP2-RCP2.6 (GDP)'!L$14*'REMIND SSP2-RCP2.6 (GDP)'!L$13 -> 0 | E4: ='REMIND SSP2-RCP2.6'!E4/'REMIND SSP2-RCP2.6 (GDP)'!M$14*'REMIND SSP2-RCP2.6 (GDP)'!M$13 -> 0 | F4: ='REMIND SSP2-RCP2.6'!F4/'REMIND SSP2-RCP2.6 (GDP)'!N$14*'REMIND SSP2-RCP2.6 (GDP)'!N$13 -> 0 | G4: ='REMIND SSP2-RCP2.6'!G4/'REMIND SSP2-RCP2.6 (GDP)'!O$14*'REMIND SSP2-RCP2.6 (GDP)'!O$13 -> 0 | H4: ='REMIND SSP2-RCP2.6'!H4/'REMIND SSP2-RCP2.6 (GDP)'!P$14*'REMIND SSP2-RCP2.6 (GDP)'!P$13 -> 0 | J4: Roadmap-30-Bio | K4: =C25/C9 -> 0.74249459 | L4: =D25/D9 -> 1.7549149 | M4: =E25/E9 -> 13.297708 | N4: =F25/F9 -> 16.8034 | O4: =G25/G9 -> 12.577169 | P4: =H25/H9 -> 2.5284198
B5: atj | C5: ='REMIND SSP2-RCP2.6'!C5/'REMIND SSP2-RCP2.6 (GDP)'!K$14*'REMIND SSP2-RCP2.6 (GDP)'!K$13 -> 0 | D5: ='REMIND SSP2-RCP2.6'!D5/'REMIND SSP2-RCP2.6 (GDP)'!L$14*'REMIND SSP2-RCP2.6 (GDP)'!L$13 -> 0 | E5: ='REMIND SSP2-RCP2.6'!E5/'REMIND SSP2-RCP2.6 (GDP)'!M$14*'REMIND SSP2-RCP2.6 (GDP)'!M$13 -> 0 | F5: ='REMIND SSP2-RCP2.6'!F5/'REMIND SSP2-RCP2.6 (GDP)'!N$14*'REMIND SSP2-RCP2.6 (GDP)'!N$13 -> 0 | G5: ='REMIND SSP2-RCP2.6'!G5/'REMIND SSP2-RCP2.6 (GDP)'!O$14*'REMIND SSP2-RCP2.6 (GDP)'!O$13 -> 0 | H5: ='REMIND SSP2-RCP2.6'!H5/'REMIND SSP2-RCP2.6 (GDP)'!P$14*'REMIND SSP2-RCP2.6 (GDP)'!P$13 -> 0 | J5: Roadmap-0 | K5: =C33/C9 -> 0.61367522 | L5: =D33/D9 -> 1.54905 | M5: =E33/E9 -> 19.871442 | N5: =F33/F9 -> 16.444805 | O5: =G33/G9 -> 21.126568 | P5: =H33/H9 -> 2.2264249
B6: ft | C6: ='REMIND SSP2-RCP2.6'!C6/'REMIND SSP2-RCP2.6 (GDP)'!K$14*'REMIND SSP2-RCP2.6 (GDP)'!K$13 -> 0 | D6: ='REMIND SSP2-RCP2.6'!D6/'REMIND SSP2-RCP2.6 (GDP)'!L$14*'REMIND SSP2-RCP2.6 (GDP)'!L$13 -> 0 | E6: ='REMIND SSP2-RCP2.6'!E6/'REMIND SSP2-RCP2.6 (GDP)'!M$14*'REMIND SSP2-RCP2.6 (GDP)'!M$13 -> 0 | F6: ='REMIND SSP2-RCP2.6'!F6/'REMIND SSP2-RCP2.6 (GDP)'!N$14*'REMIND SSP2-RCP2.6 (GDP)'!N$13 -> 0 | G6: ='REMIND SSP2-RCP2.6'!G6/'REMIND SSP2-RCP2.6 (GDP)'!O$14*'REMIND SSP2-RCP2.6 (GDP)'!O$13 -> 0 | H6: ='REMIND SSP2-RCP2.6'!H6/'REMIND SSP2-RCP2.6 (GDP)'!P$14*'REMIND SSP2-RCP2.6 (GDP)'!P$13 -> 0 | J6: Roadmap-30-Efuel | K6: =C41/C9 -> 0.77376524 | L6: =D41/D9 -> 1.5228033 | M6: =E41/E9 -> 13.913332 | N6: =F41/F9 -> 13.083277 | O6: =G41/G9 -> 14.581524 | P6: =H41/H9 -> 2.041756
B7: hefa | C7: ='REMIND SSP2-RCP2.6'!C7/'REMIND SSP2-RCP2.6 (GDP)'!K$14*'REMIND SSP2-RCP2.6 (GDP)'!K$13 -> 0 | D7: ='REMIND SSP2-RCP2.6'!D7/'REMIND SSP2-RCP2.6 (GDP)'!L$14*'REMIND SSP2-RCP2.6 (GDP)'!L$13 -> 0 | E7: ='REMIND SSP2-RCP2.6'!E7/'REMIND SSP2-RCP2.6 (GDP)'!M$14*'REMIND SSP2-RCP2.6 (GDP)'!M$13 -> 0 | F7: ='REMIND SSP2-RCP2.6'!F7/'REMIND SSP2-RCP2.6 (GDP)'!N$14*'REMIND SSP2-RCP2.6 (GDP)'!N$13 -> 0 | G7: ='REMIND SSP2-RCP2.6'!G7/'REMIND SSP2-RCP2.6 (GDP)'!O$14*'REMIND SSP2-RCP2.6 (GDP)'!O$13 -> 0 | H7: ='REMIND SSP2-RCP2.6'!H7/'REMIND SSP2-RCP2.6 (GDP)'!P$14*'REMIND SSP2-RCP2.6 (GDP)'!P$13 -> 0 | J7: Bio-Adv | K7: =C49/C9 -> 0.4185382 | L7: =D49/D9 -> 2.1927516 | M7: =E49/E9 -> 16.47049 | N7: =F49/F9 -> 28.027915 | O7: =G49/G9 -> 13.306709 | P7: =H49/H9 -> 3.8150037
B8: lh2 | C8: ='REMIND SSP2-RCP2.6'!C8/'REMIND SSP2-RCP2.6 (GDP)'!K$14*'REMIND SSP2-RCP2.6 (GDP)'!K$13 -> 0 | D8: ='REMIND SSP2-RCP2.6'!D8/'REMIND SSP2-RCP2.6 (GDP)'!L$14*'REMIND SSP2-RCP2.6 (GDP)'!L$13 -> 0 | E8: ='REMIND SSP2-RCP2.6'!E8/'REMIND SSP2-RCP2.6 (GDP)'!M$14*'REMIND SSP2-RCP2.6 (GDP)'!M$13 -> 0 | F8: ='REMIND SSP2-RCP2.6'!F8/'REMIND SSP2-RCP2.6 (GDP)'!N$14*'REMIND SSP2-RCP2.6 (GDP)'!N$13 -> 0 | G8: ='REMIND SSP2-RCP2.6'!G8/'REMIND SSP2-RCP2.6 (GDP)'!O$14*'REMIND SSP2-RCP2.6 (GDP)'!O$13 -> 0 | H8: ='REMIND SSP2-RCP2.6'!H8/'REMIND SSP2-RCP2.6 (GDP)'!P$14*'REMIND SSP2-RCP2.6 (GDP)'!P$13 -> 0 | J8: Bio-HEFA | K8: =C57/C9 -> 0.60776077 | L8: =D57/D9 -> 1.2777372 | M8: =E57/E9 -> 27.888914 | N8: =F57/F9 -> 38.728581 | O8: =G57/G9 -> 15.570348 | P8: =H57/H9 -> 6.3797538
B9: total | C9: ='REMIND SSP2-RCP2.6'!C9/'REMIND SSP2-RCP2.6 (GDP)'!K$14*'REMIND SSP2-RCP2.6 (GDP)'!K$13 -> 2.619288 | D9: ='REMIND SSP2-RCP2.6'!D9/'REMIND SSP2-RCP2.6 (GDP)'!L$14*'REMIND SSP2-RCP2.6 (GDP)'!L$13 -> 1.3399226 | E9: ='REMIND SSP2-RCP2.6'!E9/'REMIND SSP2-RCP2.6 (GDP)'!M$14*'REMIND SSP2-RCP2.6 (GDP)'!M$13 -> 0.041452716 | F9: ='REMIND SSP2-RCP2.6'!F9/'REMIND SSP2-RCP2.6 (GDP)'!N$14*'REMIND SSP2-RCP2.6 (GDP)'!N$13 -> 0.0021502218 | G9: ='REMIND SSP2-RCP2.6'!G9/'REMIND SSP2-RCP2.6 (GDP)'!O$14*'REMIND SSP2-RCP2.6 (GDP)'!O$13 -> 0.010386724 | H9: ='REMIND SSP2-RCP2.6'!H9/'REMIND SSP2-RCP2.6 (GDP)'!P$14*'REMIND SSP2-RCP2.6 (GDP)'!P$13 -> 0.010505227 | J9: Efuel-grid | K9: =C65/C9 -> 0.86951773 | L9: =D65/D9 -> 1.2161518 | M9: =E65/E9 -> 22.072827 | N9: =F65/F9 -> 8.166438 | O9: =G65/G9 -> 27.127517 | P9: =H65/H9 -> 1.1330518
A10: Roadmap-70 | B10: fk_historical | C10: ='REMIND SSP2-RCP2.6'!C10/'REMIND SSP2-RCP2.6 (GDP)'!K$14*'REMIND SSP2-RCP2.6 (GDP)'!K$13 -> 1.033283 | D10: ='REMIND SSP2-RCP2.6'!D10/'REMIND SSP2-RCP2.6 (GDP)'!L$14*'REMIND SSP2-RCP2.6 (GDP)'!L$13 -> 0.52009974 | E10: ='REMIND SSP2-RCP2.6'!E10/'REMIND SSP2-RCP2.6 (GDP)'!M$14*'REMIND SSP2-RCP2.6 (GDP)'!M$13 -> 0 | F10: ='REMIND SSP2-RCP2.6'!F10/'REMIND SSP2-RCP2.6 (GDP)'!N$14*'REMIND SSP2-RCP2.6 (GDP)'!N$13 -> 0 | G10: ='REMIND SSP2-RCP2.6'!G10/'REMIND SSP2-RCP2.6 (GDP)'!O$14*'REMIND SSP2-RCP2.6 (GDP)'!O$13 -> 0 | H10: ='REMIND SSP2-RCP2.6'!H10/'REMIND SSP2-RCP2.6 (GDP)'!P$14*'REMIND SSP2-RCP2.6 (GDP)'!P$13 -> 0 | J10: Efuel-RES | K10: =C73/C9 -> 0.70881058 | L10: =D73/D9 -> 1.0646553 | M10: =E73/E9 -> 25.121319 | N10: =F73/F9 -> 11.965255 | O10: =G73/G9 -> 11.730952 | P10: =H73/H9 -> 1.1332429
B11: fk | C11: ='REMIND SSP2-RCP2.6'!C11/'REMIND SSP2-RCP2.6 (GDP)'!K$14*'REMIND SSP2-RCP2.6 (GDP)'!K$13 -> 1.3897137 | D11: ='REMIND SSP2-RCP2.6'!D11/'REMIND SSP2-RCP2.6 (GDP)'!L$14*'REMIND SSP2-RCP2.6 (GDP)'!L$13 -> 0.71521628 | E11: ='REMIND SSP2-RCP2.6'!E11/'REMIND SSP2-RCP2.6 (GDP)'!M$14*'REMIND SSP2-RCP2.6 (GDP)'!M$13 -> 0.030268748 | F11: ='REMIND SSP2-RCP2.6'!F11/'REMIND SSP2-RCP2.6 (GDP)'!N$14*'REMIND SSP2-RCP2.6 (GDP)'!N$13 -> 0.0015700906 | G11: ='REMIND SSP2-RCP2.6'!G11/'REMIND SSP2-RCP2.6 (GDP)'!O$14*'REMIND SSP2-RCP2.6 (GDP)'!O$13 -> 0.0075843798 | H11: ='REMIND SSP2-RCP2.6'!H11/'REMIND SSP2-RCP2.6 (GDP)'!P$14*'REMIND SSP2-RCP2.6 (GDP)'!P$13 -> 0.0076709103
B12: efuels | C12: ='REMIND SSP2-RCP2.6'!C12/'REMIND SSP2-RCP2.6 (GDP)'!K$14*'REMIND SSP2-RCP2.6 (GDP)'!K$13 -> 0.05680288 | D12: ='REMIND SSP2-RCP2.6'!D12/'REMIND SSP2-RCP2.6 (GDP)'!L$14*'REMIND SSP2-RCP2.6 (GDP)'!L$13 -> 0.06973303 | E12: ='REMIND SSP2-RCP2.6'!E12/'REMIND SSP2-RCP2.6 (GDP)'!M$14*'REMIND SSP2-RCP2.6 (GDP)'!M$13 -> 0.077909307 | F12: ='REMIND SSP2-RCP2.6'!F12/'REMIND SSP2-RCP2.6 (GDP)'!N$14*'REMIND SSP2-RCP2.6 (GDP)'!N$13 -> 0.0014940822 | G12: ='REMIND SSP2-RCP2.6'!G12/'REMIND SSP2-RCP2.6 (GDP)'!O$14*'REMIND SSP2-RCP2.6 (GDP)'!O$13 -> 0.023993965 | H12: ='REMIND SSP2-RCP2.6'!H12/'REMIND SSP2-RCP2.6 (GDP)'!P$14*'REMIND SSP2-RCP2.6 (GDP)'!P$13 -> 0.0010054254 | J12: shares | K12: CC | L12: BI | M12: N | N12: P | O12: SOD | P12: FWU
B13: atj | C13: ='REMIND SSP2-RCP2.6'!C13/'REMIND SSP2-RCP2.6 (GDP)'!K$14*'REMIND SSP2-RCP2.6 (GDP)'!K$13 -> 0.0020423276 | D13: ='REMIND SSP2-RCP2.6'!D13/'REMIND SSP2-RCP2.6 (GDP)'!L$14*'REMIND SSP2-RCP2.6 (GDP)'!L$13 -> 0.019114711 | E13: ='REMIND SSP2-RCP2.6'!E13/'REMIND SSP2-RCP2.6 (GDP)'!M$14*'REMIND SSP2-RCP2.6 (GDP)'!M$13 -> 0.076304732 | F13: ='REMIND SSP2-RCP2.6'!F13/'REMIND SSP2-RCP2.6 (GDP)'!N$14*'REMIND SSP2-RCP2.6 (GDP)'!N$13 -> 0.0063584284 | G13: ='REMIND SSP2-RCP2.6'!G13/'REMIND SSP2-RCP2.6 (GDP)'!O$14*'REMIND SSP2-RCP2.6 (GDP)'!O$13 -> 0.0167132 | H13: ='REMIND SSP2-RCP2.6'!H13/'REMIND SSP2-RCP2.6 (GDP)'!P$14*'REMIND SSP2-RCP2.6 (GDP)'!P$13 -> 0.0033352501 | J13: FHN | K13: 0.9 | L13: 0.012 | M13: 0.02 | N13: 0.002 | O13: 2.2 | P13: 0.4
B14: ft | C14: ='REMIND SSP2-RCP2.6'!C14/'REMIND SSP2-RCP2.6 (GDP)'!K$14*'REMIND SSP2-RCP2.6 (GDP)'!K$13 -> -0.0728492 | D14: ='REMIND SSP2-RCP2.6'!D14/'REMIND SSP2-RCP2.6 (GDP)'!L$14*'REMIND SSP2-RCP2.6 (GDP)'!L$13 -> 0.38898589 | E14: ='REMIND SSP2-RCP2.6'!E14/'REMIND SSP2-RCP2.6 (GDP)'!M$14*'REMIND SSP2-RCP2.6 (GDP)'!M$13 -> 0.011736639 | F14: ='REMIND SSP2-RCP2.6'!F14/'REMIND SSP2-RCP2.6 (GDP)'!N$14*'REMIND SSP2-RCP2.6 (GDP)'!N$13 -> 0.00222998 | G14: ='REMIND SSP2-RCP2.6'!G14/'REMIND SSP2-RCP2.6 (GDP)'!O$14*'REMIND SSP2-RCP2.6 (GDP)'!O$13 -> 0.0042446622 | H14: ='REMIND SSP2-RCP2.6'!H14/'REMIND SSP2-RCP2.6 (GDP)'!P$14*'REMIND SSP2-RCP2.6 (GDP)'!P$13 -> 0.0018570609 | J14: GDP | K14: 2.9 | L14: 2.9 | M14: 2.9 | N14: 2.9 | O14: 2.9 | P14: 2.9
B15: hefa | C15: ='REMIND SSP2-RCP2.6'!C15/'REMIND SSP2-RCP2.6 (GDP)'!K$14*'REMIND SSP2-RCP2.6 (GDP)'!K$13 -> 0.0034584669 | D15: ='REMIND SSP2-RCP2.6'!D15/'REMIND SSP2-RCP2.6 (GDP)'!L$14*'REMIND SSP2-RCP2.6 (GDP)'!L$13 -> 0.0047106401 | E15: ='REMIND SSP2-RCP2.6'!E15/'REMIND SSP2-RCP2.6 (GDP)'!M$14*'REMIND SSP2-RCP2.6 (GDP)'!M$13 -> 0.039703798 | F15: ='REMIND SSP2-RCP2.6'!F15/'REMIND SSP2-RCP2.6 (GDP)'!N$14*'REMIND SSP2-RCP2.6 (GDP)'!N$13 -> 0.0026903886 | G15: ='REMIND SSP2-RCP2.6'!G15/'REMIND SSP2-RCP2.6 (GDP)'!O$14*'REMIND SSP2-RCP2.6 (GDP)'!O$13 -> 0.0048989151 | H15: ='REMIND SSP2-RCP2.6'!H15/'REMIND SSP2-RCP2.6 (GDP)'!P$14*'REMIND SSP2-RCP2.6 (GDP)'!P$13 -> 0.0022919645
B16: lh2 | C16: ='REMIND SSP2-RCP2.6'!C16/'REMIND SSP2-RCP2.6 (GDP)'!K$14*'REMIND SSP2-RCP2.6 (GDP)'!K$13 -> 0 | D16: ='REMIND SSP2-RCP2.6'!D16/'REMIND SSP2-RCP2.6 (GDP)'!L$14*'REMIND SSP2-RCP2.6 (GDP)'!L$13 -> 0 | E16: ='REMIND SSP2-RCP2.6'!E16/'REMIND SSP2-RCP2.6 (GDP)'!M$14*'REMIND SSP2-RCP2.6 (GDP)'!M$13 -> 0 | F16: ='REMIND SSP2-RCP2.6'!F16/'REMIND SSP2-RCP2.6 (GDP)'!N$14*'REMIND SSP2-RCP2.6 (GDP)'!N$13 -> 0 | G16: ='REMIND SSP2-RCP2.6'!G16/'REMIND SSP2-RCP2.6 (GDP)'!O$14*'REMIND SSP2-RCP2.6 (GDP)'!O$13 -> 0 | H16: ='REMIND SSP2-RCP2.6'!H16/'REMIND SSP2-RCP2.6 (GDP)'!P$14*'REMIND SSP2-RCP2.6 (GDP)'!P$13 -> 0
B17: total | C17: ='REMIND SSP2-RCP2.6'!C17/'REMIND SSP2-RCP2.6 (GDP)'!K$14*'REMIND SSP2-RCP2.6 (GDP)'!K$13 -> 2.4124512 | D17: ='REMIND SSP2-RCP2.6'!D17/'REMIND SSP2-RCP2.6 (GDP)'!L$14*'REMIND SSP2-RCP2.6 (GDP)'!L$13 -> 1.7178603 | E17: ='REMIND SSP2-RCP2.6'!E17/'REMIND SSP2-RCP2.6 (GDP)'!M$14*'REMIND SSP2-RCP2.6 (GDP)'!M$13 -> 0.23592322 | F17: ='REMIND SSP2-RCP2.6'!F17/'REMIND SSP2-RCP2.6 (GDP)'!N$14*'REMIND SSP2-RCP2.6 (GDP)'!N$13 -> 0.01434297 | G17: ='REMIND SSP2-RCP2.6'!G17/'REMIND SSP2-RCP2.6 (GDP)'!O$14*'REMIND SSP2-RCP2.6 (GDP)'!O$13 -> 0.057435122 | H17: ='REMIND SSP2-RCP2.6'!H17/'REMIND SSP2-RCP2.6 (GDP)'!P$14*'REMIND SSP2-RCP2.6 (GDP)'!P$13 -> 0.016160611
A18: Roadmap-30-Bio | B18: fk_historical | C18: ='REMIND SSP2-RCP2.6'!C18/'REMIND SSP2-RCP2.6 (GDP)'!K$14*'REMIND SSP2-RCP2.6 (GDP)'!K$13 -> 1.033283 | D18: ='REMIND SSP2-RCP2.6'!D18/'REMIND SSP2-RCP2.6 (GDP)'!L$14*'REMIND SSP2-RCP2.6 (GDP)'!L$13 -> 0.52009974 | E18: ='REMIND SSP2-RCP2.6'!E18/'REMIND SSP2-RCP2.6 (GDP)'!M$14*'REMIND SSP2-RCP2.6 (GDP)'!M$13 -> 0 | F18: ='REMIND SSP2-RCP2.6'!F18/'REMIND SSP2-RCP2.6 (GDP)'!N$14*'REMIND SSP2-RCP2.6 (GDP)'!N$13 -> 0 | G18: ='REMIND SSP2-RCP2.6'!G18/'REMIND SSP2-RCP2.6 (GDP)'!O$14*'REMIND SSP2-RCP2.6 (GDP)'!O$13 -> 0 | H18: ='REMIND SSP2-RCP2.6'!H18/'REMIND SSP2-RCP2.6 (GDP)'!P$14*'REMIND SSP2-RCP2.6 (GDP)'!P$13 -> 0
B19: fk | C19: ='REMIND SSP2-RCP2.6'!C19/'REMIND SSP2-RCP2.6 (GDP)'!K$14*'REMIND SSP2-RCP2.6 (GDP)'!K$13 -> 0.96422647 | D19: ='REMIND SSP2-RCP2.6'!D19/'REMIND SSP2-RCP2.6 (GDP)'!L$14*'REMIND SSP2-RCP2.6 (GDP)'!L$13 -> 0.49139389 | E19: ='REMIND SSP2-RCP2.6'!E19/'REMIND SSP2-RCP2.6 (GDP)'!M$14*'REMIND SSP2-RCP2.6 (GDP)'!M$13 -> 0.011664755 | F19: ='REMIND SSP2-RCP2.6'!F19/'REMIND SSP2-RCP2.6 (GDP)'!N$14*'REMIND SSP2-RCP2.6 (GDP)'!N$13 -> 0.00060507035 | G19: ='REMIND SSP2-RCP2.6'!G19/'REMIND SSP2-RCP2.6 (GDP)'!O$14*'REMIND SSP2-RCP2.6 (GDP)'!O$13 -> 0.0029228143 | H19: ='REMIND SSP2-RCP2.6'!H19/'REMIND SSP2-RCP2.6 (GDP)'!P$14*'REMIND SSP2-RCP2.6 (GDP)'!P$13 -> 0.0029561608
B20: efuels | C20: ='REMIND SSP2-RCP2.6'!C20/'REMIND SSP2-RCP2.6 (GDP)'!K$14*'REMIND SSP2-RCP2.6 (GDP)'!K$13 -> 0.19613127 | D20: ='REMIND SSP2-RCP2.6'!D20/'REMIND SSP2-RCP2.6 (GDP)'!L$14*'REMIND SSP2-RCP2.6 (GDP)'!L$13 -> 0.1912691 | E20: ='REMIND SSP2-RCP2.6'!E20/'REMIND SSP2-RCP2.6 (GDP)'!M$14*'REMIND SSP2-RCP2.6 (GDP)'!M$13 -> 0.17525563 | F20: ='REMIND SSP2-RCP2.6'!F20/'REMIND SSP2-RCP2.6 (GDP)'!N$14*'REMIND SSP2-RCP2.6 (GDP)'!N$13 -> 0.0033609118 | G20: ='REMIND SSP2-RCP2.6'!G20/'REMIND SSP2-RCP2.6 (GDP)'!O$14*'REMIND SSP2-RCP2.6 (GDP)'!O$13 -> 0.053974006 | H20: ='REMIND SSP2-RCP2.6'!H20/'REMIND SSP2-RCP2.6 (GDP)'!P$14*'REMIND SSP2-RCP2.6 (GDP)'!P$13 -> 0.0022616868
B21: atj | C21: ='REMIND SSP2-RCP2.6'!C21/'REMIND SSP2-RCP2.6 (GDP)'!K$14*'REMIND SSP2-RCP2.6 (GDP)'!K$13 -> 0.008491428 | D21: ='REMIND SSP2-RCP2.6'!D21/'REMIND SSP2-RCP2.6 (GDP)'!L$14*'REMIND SSP2-RCP2.6 (GDP)'!L$13 -> 0.055854106 | E21: ='REMIND SSP2-RCP2.6'!E21/'REMIND SSP2-RCP2.6 (GDP)'!M$14*'REMIND SSP2-RCP2.6 (GDP)'!M$13 -> 0.21760705 | F21: ='REMIND SSP2-RCP2.6'!F21/'REMIND SSP2-RCP2.6 (GDP)'!N$14*'REMIND SSP2-RCP2.6 (GDP)'!N$13 -> 0.018133068 | G21: ='REMIND SSP2-RCP2.6'!G21/'REMIND SSP2-RCP2.6 (GDP)'!O$14*'REMIND SSP2-RCP2.6 (GDP)'!O$13 -> 0.04766297 | H21: ='REMIND SSP2-RCP2.6'!H21/'REMIND SSP2-RCP2.6 (GDP)'!P$14*'REMIND SSP2-RCP2.6 (GDP)'!P$13 -> 0.0095115193
B22: ft | C22: ='REMIND SSP2-RCP2.6'!C22/'REMIND SSP2-RCP2.6 (GDP)'!K$14*'REMIND SSP2-RCP2.6 (GDP)'!K$13 -> -0.27035806 | D22: ='REMIND SSP2-RCP2.6'!D22/'REMIND SSP2-RCP2.6 (GDP)'!L$14*'REMIND SSP2-RCP2.6 (GDP)'!L$13 -> 1.0778039 | E22: ='REMIND SSP2-RCP2.6'!E22/'REMIND SSP2-RCP2.6 (GDP)'!M$14*'REMIND SSP2-RCP2.6 (GDP)'!M$13 -> 0.033470733 | F22: ='REMIND SSP2-RCP2.6'!F22/'REMIND SSP2-RCP2.6 (GDP)'!N$14*'REMIND SSP2-RCP2.6 (GDP)'!N$13 -> 0.0063594925 | G22: ='REMIND SSP2-RCP2.6'!G22/'REMIND SSP2-RCP2.6 (GDP)'!O$14*'REMIND SSP2-RCP2.6 (GDP)'!O$13 -> 0.012104995 | H22: ='REMIND SSP2-RCP2.6'!H22/'REMIND SSP2-RCP2.6 (GDP)'!P$14*'REMIND SSP2-RCP2.6 (GDP)'!P$13 -> 0.005295996
B23: hefa | C23: ='REMIND SSP2-RCP2.6'!C23/'REMIND SSP2-RCP2.6 (GDP)'!K$14*'REMIND SSP2-RCP2.6 (GDP)'!K$13 -> 0.013033076 | D23: ='REMIND SSP2-RCP2.6'!D23/'REMIND SSP2-RCP2.6 (GDP)'!L$14*'REMIND SSP2-RCP2.6 (GDP)'!L$13 -> 0.015029571 | E23: ='REMIND SSP2-RCP2.6'!E23/'REMIND SSP2-RCP2.6 (GDP)'!M$14*'REMIND SSP2-RCP2.6 (GDP)'!M$13 -> 0.11322792 | F23: ='REMIND SSP2-RCP2.6'!F23/'REMIND SSP2-RCP2.6 (GDP)'!N$14*'REMIND SSP2-RCP2.6 (GDP)'!N$13 -> 0.0076724932 | G23: ='REMIND SSP2-RCP2.6'!G23/'REMIND SSP2-RCP2.6 (GDP)'!O$14*'REMIND SSP2-RCP2.6 (GDP)'!O$13 -> 0.013970804 | H23: ='REMIND SSP2-RCP2.6'!H23/'REMIND SSP2-RCP2.6 (GDP)'!P$14*'REMIND SSP2-RCP2.6 (GDP)'!P$13 -> 0.0065362608
B24: lh2 | C24: ='REMIND SSP2-RCP2.6'!C24/'REMIND SSP2-RCP2.6 (GDP)'!K$14*'REMIND SSP2-RCP2.6 (GDP)'!K$13 -> 0 | D24: ='REMIND SSP2-RCP2.6'!D24/'REMIND SSP2-RCP2.6 (GDP)'!L$14*'REMIND SSP2-RCP2.6 (GDP)'!L$13 -> 0 | E24: ='REMIND SSP2-RCP2.6'!E24/'REMIND SSP2-RCP2.6 (GDP)'!M$14*'REMIND SSP2-RCP2.6 (GDP)'!M$13 -> 0 | F24: ='REMIND SSP2-RCP2.6'!F24/'REMIND SSP2-RCP2.6 (GDP)'!N$14*'REMIND SSP2-RCP2.6 (GDP)'!N$13 -> 0 | G24: ='REMIND SSP2-RCP2.6'!G24/'REMIND SSP2-RCP2.6 (GDP)'!O$14*'REMIND SSP2-RCP2.6 (GDP)'!O$13 -> 0 | H24: ='REMIND SSP2-RCP2.6'!H24/'REMIND SSP2-RCP2.6 (GDP)'!P$14*'REMIND SSP2-RCP2.6 (GDP)'!P$13 -> 0
B25: total | C25: ='REMIND SSP2-RCP2.6'!C25/'REMIND SSP2-RCP2.6 (GDP)'!K$14*'REMIND SSP2-RCP2.6 (GDP)'!K$13 -> 1.9448072 | D25: ='REMIND SSP2-RCP2.6'!D25/'REMIND SSP2-RCP2.6 (GDP)'!L$14*'REMIND SSP2-RCP2.6 (GDP)'!L$13 -> 2.3514503 | E25: ='REMIND SSP2-RCP2.6'!E25/'REMIND SSP2-RCP2.6 (GDP)'!M$14*'REMIND SSP2-RCP2.6 (GDP)'!M$13 -> 0.55122609 | F25: ='REMIND SSP2-RCP2.6'!F25/'REMIND SSP2-RCP2.6 (GDP)'!N$14*'REMIND SSP2-RCP2.6 (GDP)'!N$13 -> 0.036131035 | G25: ='REMIND SSP2-RCP2.6'!G25/'REMIND SSP2-RCP2.6 (GDP)'!O$14*'REMIND SSP2-RCP2.6 (GDP)'!O$13 -> 0.13063559 | H25: ='REMIND SSP2-RCP2.6'!H25/'REMIND SSP2-RCP2.6 (GDP)'!P$14*'REMIND SSP2-RCP2.6 (GDP)'!P$13 -> 0.026561624
A26: Roadmap-0 | B26: fk_historical | C26: ='REMIND SSP2-RCP2.6'!C26/'REMIND SSP2-RCP2.6 (GDP)'!K$14*'REMIND SSP2-RCP2.6 (GDP)'!K$13 -> 1.033283 | D26: ='REMIND SSP2-RCP2.6'!D26/'REMIND SSP2-RCP2.6 (GDP)'!L$14*'REMIND SSP2-RCP2.6 (GDP)'!L$13 -> 0.52009974 | E26: ='REMIND SSP2-RCP2.6'!E26/'REMIND SSP2-RCP2.6 (GDP)'!M$14*'REMIND SSP2-RCP2.6 (GDP)'!M$13 -> 0 | F26: ='REMIND SSP2-RCP2.6'!F26/'REMIND SSP2-RCP2.6 (GDP)'!N$14*'REMIND SSP2-RCP2.6 (GDP)'!N$13 -> 0 | G26: ='REMIND SSP2-RCP2.6'!G26/'REMIND SSP2-RCP2.6 (GDP)'!O$14*'REMIND SSP2-RCP2.6 (GDP)'!O$13 -> 0 | H26: ='REMIND SSP2-RCP2.6'!H26/'REMIND SSP2-RCP2.6 (GDP)'!P$14*'REMIND SSP2-RCP2.6 (GDP)'!P$13 -> 0
B27: fk | C27: ='REMIND SSP2-RCP2.6'!C27/'REMIND SSP2-RCP2.6 (GDP)'!K$14*'REMIND SSP2-RCP2.6 (GDP)'!K$13 -> 0.5532467 | D27: ='REMIND SSP2-RCP2.6'!D27/'REMIND SSP2-RCP2.6 (GDP)'!L$14*'REMIND SSP2-RCP2.6 (GDP)'!L$13 -> 0.27847499 | E27: ='REMIND SSP2-RCP2.6'!E27/'REMIND SSP2-RCP2.6 (GDP)'!M$14*'REMIND SSP2-RCP2.6 (GDP)'!M$13 -> 0 | F27: ='REMIND SSP2-RCP2.6'!F27/'REMIND SSP2-RCP2.6 (GDP)'!N$14*'REMIND SSP2-RCP2.6 (GDP)'!N$13 -> 0 | G27: ='REMIND SSP2-RCP2.6'!G27/'REMIND SSP2-RCP2.6 (GDP)'!O$14*'REMIND SSP2-RCP2.6 (GDP)'!O$13 -> 0 | H27: ='REMIND SSP2-RCP2.6'!H27/'REMIND SSP2-RCP2.6 (GDP)'!P$14*'REMIND SSP2-RCP2.6 (GDP)'!P$13 -> 0
B28: efuels | C28: ='REMIND SSP2-RCP2.6'!C28/'REMIND SSP2-RCP2.6 (GDP)'!K$14*'REMIND SSP2-RCP2.6 (GDP)'!K$13 -> 0.34537984 | D28: ='REMIND SSP2-RCP2.6'!D28/'REMIND SSP2-RCP2.6 (GDP)'!L$14*'REMIND SSP2-RCP2.6 (GDP)'!L$13 -> 0.44283755 | E28: ='REMIND SSP2-RCP2.6'!E28/'REMIND SSP2-RCP2.6 (GDP)'!M$14*'REMIND SSP2-RCP2.6 (GDP)'!M$13 -> 0.50938753 | F28: ='REMIND SSP2-RCP2.6'!F28/'REMIND SSP2-RCP2.6 (GDP)'!N$14*'REMIND SSP2-RCP2.6 (GDP)'!N$13 -> 0.0097686251 | G28: ='REMIND SSP2-RCP2.6'!G28/'REMIND SSP2-RCP2.6 (GDP)'!O$14*'REMIND SSP2-RCP2.6 (GDP)'!O$13 -> 0.15687762 | H28: ='REMIND SSP2-RCP2.6'!H28/'REMIND SSP2-RCP2.6 (GDP)'!P$14*'REMIND SSP2-RCP2.6 (GDP)'!P$13 -> 0.0065736836
B29: atj | C29: ='REMIND SSP2-RCP2.6'!C29/'REMIND SSP2-RCP2.6 (GDP)'!K$14*'REMIND SSP2-RCP2.6 (GDP)'!K$13 -> 0.013664324 | D29: ='REMIND SSP2-RCP2.6'!D29/'REMIND SSP2-RCP2.6 (GDP)'!L$14*'REMIND SSP2-RCP2.6 (GDP)'!L$13 -> 0.046867875 | E29: ='REMIND SSP2-RCP2.6'!E29/'REMIND SSP2-RCP2.6 (GDP)'!M$14*'REMIND SSP2-RCP2.6 (GDP)'!M$13 -> 0.16871086 | F29: ='REMIND SSP2-RCP2.6'!F29/'REMIND SSP2-RCP2.6 (GDP)'!N$14*'REMIND SSP2-RCP2.6 (GDP)'!N$13 -> 0.014058577 | G29: ='REMIND SSP2-RCP2.6'!G29/'REMIND SSP2-RCP2.6 (GDP)'!O$14*'REMIND SSP2-RCP2.6 (GDP)'!O$13 -> 0.036953126 | H29: ='REMIND SSP2-RCP2.6'!H29/'REMIND SSP2-RCP2.6 (GDP)'!P$14*'REMIND SSP2-RCP2.6 (GDP)'!P$13 -> 0.0073742861
B30: ft | C30: ='REMIND SSP2-RCP2.6'!C30/'REMIND SSP2-RCP2.6 (GDP)'!K$14*'REMIND SSP2-RCP2.6 (GDP)'!K$13 -> -0.36070661 | D30: ='REMIND SSP2-RCP2.6'!D30/'REMIND SSP2-RCP2.6 (GDP)'!L$14*'REMIND SSP2-RCP2.6 (GDP)'!L$13 -> 0.75956729 | E30: ='REMIND SSP2-RCP2.6'!E30/'REMIND SSP2-RCP2.6 (GDP)'!M$14*'REMIND SSP2-RCP2.6 (GDP)'!M$13 -> 0.025949878 | F30: ='REMIND SSP2-RCP2.6'!F30/'REMIND SSP2-RCP2.6 (GDP)'!N$14*'REMIND SSP2-RCP2.6 (GDP)'!N$13 -> 0.004930518 | G30: ='REMIND SSP2-RCP2.6'!G30/'REMIND SSP2-RCP2.6 (GDP)'!O$14*'REMIND SSP2-RCP2.6 (GDP)'!O$13 -> 0.0093850094 | H30: ='REMIND SSP2-RCP2.6'!H30/'REMIND SSP2-RCP2.6 (GDP)'!P$14*'REMIND SSP2-RCP2.6 (GDP)'!P$13 -> 0.0041059886
B31: hefa | C31: ='REMIND SSP2-RCP2.6'!C31/'REMIND SSP2-RCP2.6 (GDP)'!K$14*'REMIND SSP2-RCP2.6 (GDP)'!K$13 -> 0.017895183 | D31: ='REMIND SSP2-RCP2.6'!D31/'REMIND SSP2-RCP2.6 (GDP)'!L$14*'REMIND SSP2-RCP2.6 (GDP)'!L$13 -> 0.015573825 | E31: ='REMIND SSP2-RCP2.6'!E31/'REMIND SSP2-RCP2.6 (GDP)'!M$14*'REMIND SSP2-RCP2.6 (GDP)'!M$13 -> 0.08778567 | F31: ='REMIND SSP2-RCP2.6'!F31/'REMIND SSP2-RCP2.6 (GDP)'!N$14*'REMIND SSP2-RCP2.6 (GDP)'!N$13 -> 0.0059484881 | G31: ='REMIND SSP2-RCP2.6'!G31/'REMIND SSP2-RCP2.6 (GDP)'!O$14*'REMIND SSP2-RCP2.6 (GDP)'!O$13 -> 0.010831572 | H31: ='REMIND SSP2-RCP2.6'!H31/'REMIND SSP2-RCP2.6 (GDP)'!P$14*'REMIND SSP2-RCP2.6 (GDP)'!P$13 -> 0.0050675665
B32: lh2 | C32: ='REMIND SSP2-RCP2.6'!C32/'REMIND SSP2-RCP2.6 (GDP)'!K$14*'REMIND SSP2-RCP2.6 (GDP)'!K$13 -> 0.0046297146 | D32: ='REMIND SSP2-RCP2.6'!D32/'REMIND SSP2-RCP2.6 (GDP)'!L$14*'REMIND SSP2-RCP2.6 (GDP)'!L$13 -> 0.012185851 | E32: ='REMIND SSP2-RCP2.6'!E32/'REMIND SSP2-RCP2.6 (GDP)'!M$14*'REMIND SSP2-RCP2.6 (GDP)'!M$13 -> 0.0318913 | F32: ='REMIND SSP2-RCP2.6'!F32/'REMIND SSP2-RCP2.6 (GDP)'!N$14*'REMIND SSP2-RCP2.6 (GDP)'!N$13 -> 0.00065376948 | G32: ='REMIND SSP2-RCP2.6'!G32/'REMIND SSP2-RCP2.6 (GDP)'!O$14*'REMIND SSP2-RCP2.6 (GDP)'!O$13 -> 0.0053885145 | H32: ='REMIND SSP2-RCP2.6'!H32/'REMIND SSP2-RCP2.6 (GDP)'!P$14*'REMIND SSP2-RCP2.6 (GDP)'!P$13 -> 0.00026757365
B33: total | C33: ='REMIND SSP2-RCP2.6'!C33/'REMIND SSP2-RCP2.6 (GDP)'!K$14*'REMIND SSP2-RCP2.6 (GDP)'!K$13 -> 1.6073921 | D33: ='REMIND SSP2-RCP2.6'!D33/'REMIND SSP2-RCP2.6 (GDP)'!L$14*'REMIND SSP2-RCP2.6 (GDP)'!L$13 -> 2.0756071 | E33: ='REMIND SSP2-RCP2.6'!E33/'REMIND SSP2-RCP2.6 (GDP)'!M$14*'REMIND SSP2-RCP2.6 (GDP)'!M$13 -> 0.82372524 | F33: ='REMIND SSP2-RCP2.6'!F33/'REMIND SSP2-RCP2.6 (GDP)'!N$14*'REMIND SSP2-RCP2.6 (GDP)'!N$13 -> 0.035359978 | G33: ='REMIND SSP2-RCP2.6'!G33/'REMIND SSP2-RCP2.6 (GDP)'!O$14*'REMIND SSP2-RCP2.6 (GDP)'!O$13 -> 0.21943584 | H33: ='REMIND SSP2-RCP2.6'!H33/'REMIND SSP2-RCP2.6 (GDP)'!P$14*'REMIND SSP2-RCP2.6 (GDP)'!P$13 -> 0.023389098
A34: Roadmap-30-Efuel | B34: fk_historical | C34: ='REMIND SSP2-RCP2.6'!C34/'REMIND SSP2-RCP2.6 (GDP)'!K$14*'REMIND SSP2-RCP2.6 (GDP)'!K$13 -> 1.033283 | D34: ='REMIND SSP2-RCP2.6'!D34/'REMIND SSP2-RCP2.6 (GDP)'!L$14*'REMIND SSP2-RCP2.6 (GDP)'!L$13 -> 0.52009974 | E34: ='REMIND SSP2-RCP2.6'!E34/'REMIND SSP2-RCP2.6 (GDP)'!M$14*'REMIND SSP2-RCP2.6 (GDP)'!M$13 -> 0 | F34: ='REMIND SSP2-RCP2.6'!F34/'REMIND SSP2-RCP2.6 (GDP)'!N$14*'REMIND SSP2-RCP2.6 (GDP)'!N$13 -> 0 | G34: ='REMIND SSP2-RCP2.6'!G34/'REMIND SSP2-RCP2.6 (GDP)'!O$14*'REMIND SSP2-RCP2.6 (GDP)'!O$13 -> 0 | H34: ='REMIND SSP2-RCP2.6'!H34/'REMIND SSP2-RCP2.6 (GDP)'!P$14*'REMIND SSP2-RCP2.6 (GDP)'!P$13 -> 0
B35: fk | C35: ='REMIND SSP2-RCP2.6'!C35/'REMIND SSP2-RCP2.6 (GDP)'!K$14*'REMIND SSP2-RCP2.6 (GDP)'!K$13 -> 1.0747833 | D35: ='REMIND SSP2-RCP2.6'!D35/'REMIND SSP2-RCP2.6 (GDP)'!L$14*'REMIND SSP2-RCP2.6 (GDP)'!L$13 -> 0.54744247 | E35: ='REMIND SSP2-RCP2.6'!E35/'REMIND SSP2-RCP2.6 (GDP)'!M$14*'REMIND SSP2-RCP2.6 (GDP)'!M$13 -> 0.012435815 | F35: ='REMIND SSP2-RCP2.6'!F35/'REMIND SSP2-RCP2.6 (GDP)'!N$14*'REMIND SSP2-RCP2.6 (GDP)'!N$13 -> 0.00064506653 | G35: ='REMIND SSP2-RCP2.6'!G35/'REMIND SSP2-RCP2.6 (GDP)'!O$14*'REMIND SSP2-RCP2.6 (GDP)'!O$13 -> 0.0031160173 | H35: ='REMIND SSP2-RCP2.6'!H35/'REMIND SSP2-RCP2.6 (GDP)'!P$14*'REMIND SSP2-RCP2.6 (GDP)'!P$13 -> 0.0031515681
B36: efuels | C36: ='REMIND SSP2-RCP2.6'!C36/'REMIND SSP2-RCP2.6 (GDP)'!K$14*'REMIND SSP2-RCP2.6 (GDP)'!K$13 -> 0.10454651 | D36: ='REMIND SSP2-RCP2.6'!D36/'REMIND SSP2-RCP2.6 (GDP)'!L$14*'REMIND SSP2-RCP2.6 (GDP)'!L$13 -> 0.22328804 | E36: ='REMIND SSP2-RCP2.6'!E36/'REMIND SSP2-RCP2.6 (GDP)'!M$14*'REMIND SSP2-RCP2.6 (GDP)'!M$13 -> 0.32318678 | F36: ='REMIND SSP2-RCP2.6'!F36/'REMIND SSP2-RCP2.6 (GDP)'!N$14*'REMIND SSP2-RCP2.6 (GDP)'!N$13 -> 0.0061978167 | G36: ='REMIND SSP2-RCP2.6'!G36/'REMIND SSP2-RCP2.6 (GDP)'!O$14*'REMIND SSP2-RCP2.6 (GDP)'!O$13 -> 0.099532811 | H36: ='REMIND SSP2-RCP2.6'!H36/'REMIND SSP2-RCP2.6 (GDP)'!P$14*'REMIND SSP2-RCP2.6 (GDP)'!P$13 -> 0.0041707493
B37: atj | C37: ='REMIND SSP2-RCP2.6'!C37/'REMIND SSP2-RCP2.6 (GDP)'!K$14*'REMIND SSP2-RCP2.6 (GDP)'!K$13 -> 0.0072462589 | D37: ='REMIND SSP2-RCP2.6'!D37/'REMIND SSP2-RCP2.6 (GDP)'!L$14*'REMIND SSP2-RCP2.6 (GDP)'!L$13 -> 0.037786587 | E37: ='REMIND SSP2-RCP2.6'!E37/'REMIND SSP2-RCP2.6 (GDP)'!M$14*'REMIND SSP2-RCP2.6 (GDP)'!M$13 -> 0.14402745 | F37: ='REMIND SSP2-RCP2.6'!F37/'REMIND SSP2-RCP2.6 (GDP)'!N$14*'REMIND SSP2-RCP2.6 (GDP)'!N$13 -> 0.012001723 | G37: ='REMIND SSP2-RCP2.6'!G37/'REMIND SSP2-RCP2.6 (GDP)'!O$14*'REMIND SSP2-RCP2.6 (GDP)'!O$13 -> 0.031546661 | H37: ='REMIND SSP2-RCP2.6'!H37/'REMIND SSP2-RCP2.6 (GDP)'!P$14*'REMIND SSP2-RCP2.6 (GDP)'!P$13 -> 0.0062953836
B38: ft | C38: ='REMIND SSP2-RCP2.6'!C38/'REMIND SSP2-RCP2.6 (GDP)'!K$14*'REMIND SSP2-RCP2.6 (GDP)'!K$13 -> -0.20312063 | D38: ='REMIND SSP2-RCP2.6'!D38/'REMIND SSP2-RCP2.6 (GDP)'!L$14*'REMIND SSP2-RCP2.6 (GDP)'!L$13 -> 0.70119503 | E38: ='REMIND SSP2-RCP2.6'!E38/'REMIND SSP2-RCP2.6 (GDP)'!M$14*'REMIND SSP2-RCP2.6 (GDP)'!M$13 -> 0.022153254 | F38: ='REMIND SSP2-RCP2.6'!F38/'REMIND SSP2-RCP2.6 (GDP)'!N$14*'REMIND SSP2-RCP2.6 (GDP)'!N$13 -> 0.0042091535 | G38: ='REMIND SSP2-RCP2.6'!G38/'REMIND SSP2-RCP2.6 (GDP)'!O$14*'REMIND SSP2-RCP2.6 (GDP)'!O$13 -> 0.008011926 | H38: ='REMIND SSP2-RCP2.6'!H38/'REMIND SSP2-RCP2.6 (GDP)'!P$14*'REMIND SSP2-RCP2.6 (GDP)'!P$13 -> 0.0035052577
B39: hefa | C39: ='REMIND SSP2-RCP2.6'!C39/'REMIND SSP2-RCP2.6 (GDP)'!K$14*'REMIND SSP2-RCP2.6 (GDP)'!K$13 -> 0.0099755836 | D39: ='REMIND SSP2-RCP2.6'!D39/'REMIND SSP2-RCP2.6 (GDP)'!L$14*'REMIND SSP2-RCP2.6 (GDP)'!L$13 -> 0.010626824 | E39: ='REMIND SSP2-RCP2.6'!E39/'REMIND SSP2-RCP2.6 (GDP)'!M$14*'REMIND SSP2-RCP2.6 (GDP)'!M$13 -> 0.074942098 | F39: ='REMIND SSP2-RCP2.6'!F39/'REMIND SSP2-RCP2.6 (GDP)'!N$14*'REMIND SSP2-RCP2.6 (GDP)'!N$13 -> 0.0050781885 | G39: ='REMIND SSP2-RCP2.6'!G39/'REMIND SSP2-RCP2.6 (GDP)'!O$14*'REMIND SSP2-RCP2.6 (GDP)'!O$13 -> 0.0092468478 | H39: ='REMIND SSP2-RCP2.6'!H39/'REMIND SSP2-RCP2.6 (GDP)'!P$14*'REMIND SSP2-RCP2.6 (GDP)'!P$13 -> 0.004326151
B40: lh2 | C40: ='REMIND SSP2-RCP2.6'!C40/'REMIND SSP2-RCP2.6 (GDP)'!K$14*'REMIND SSP2-RCP2.6 (GDP)'!K$13 -> 0 | D40: ='REMIND SSP2-RCP2.6'!D40/'REMIND SSP2-RCP2.6 (GDP)'!L$14*'REMIND SSP2-RCP2.6 (GDP)'!L$13 -> 0 | E40: ='REMIND SSP2-RCP2.6'!E40/'REMIND SSP2-RCP2.6 (GDP)'!M$14*'REMIND SSP2-RCP2.6 (GDP)'!M$13 -> 0 | F40: ='REMIND SSP2-RCP2.6'!F40/'REMIND SSP2-RCP2.6 (GDP)'!N$14*'REMIND SSP2-RCP2.6 (GDP)'!N$13 -> 0 | G40: ='REMIND SSP2-RCP2.6'!G40/'REMIND SSP2-RCP2.6 (GDP)'!O$14*'REMIND SSP2-RCP2.6 (GDP)'!O$13 -> 0 | H40: ='REMIND SSP2-RCP2.6'!H40/'REMIND SSP2-RCP2.6 (GDP)'!P$14*'REMIND SSP2-RCP2.6 (GDP)'!P$13 -> 0
...

Sheet REMIND SSP1-RCP1.9 (GDP)
C1: CC | D1: BI | E1: N | F1: P | G1: SOD | H1: FWU | K1: Ratios to baseline
A2: Baseline | B2: fk_historical | C2: ='REMIND SSP1-RCP1.9'!C2/K$14*K$13 -> 1.033283 | D2: ='REMIND SSP1-RCP1.9'!D2/L$14*L$13 -> 0.52009974 | E2: ='REMIND SSP1-RCP1.9'!E2/M$14*M$13 -> 0 | F2: ='REMIND SSP1-RCP1.9'!F2/N$14*N$13 -> 0 | G2: ='REMIND SSP1-RCP1.9'!G2/O$14*O$13 -> 0 | H2: ='REMIND SSP1-RCP1.9'!H2/P$14*P$13 -> 0 | K2: CC | L2: BI | M2: N | N2: P | O2: SOD | P2: FWU
B3: fk | C3: ='REMIND SSP1-RCP1.9'!C3/K$14*K$13 -> 1.580494 | D3: ='REMIND SSP1-RCP1.9'!D3/L$14*L$13 -> 0.83296174 | E3: ='REMIND SSP1-RCP1.9'!E3/M$14*M$13 -> 0.035771037 | F3: ='REMIND SSP1-RCP1.9'!F3/N$14*N$13 -> 0.0021431362 | G3: ='REMIND SSP1-RCP1.9'!G3/O$14*O$13 -> 0.017561993 | H3: ='REMIND SSP1-RCP1.9'!H3/P$14*P$13 -> 0.010575417 | J3: Roadmap-70 | K3: =C17/C9 -> 0.93858639 | L3: =D17/D9 -> 1.603028 | M3: =E17/E9 -> 4.7419332 | N3: =F17/F9 -> 4.8630225 | O3: =G17/G9 -> 4.9213427 | P3: =H17/H9 -> 1.409048
B4: efuels | C4: ='REMIND SSP1-RCP1.9'!C4/K$14*K$13 -> 0 | D4: ='REMIND SSP1-RCP1.9'!D4/L$14*L$13 -> 0 | E4: ='REMIND SSP1-RCP1.9'!E4/M$14*M$13 -> 0 | F4: ='REMIND SSP1-RCP1.9'!F4/N$14*N$13 -> 0 | G4: ='REMIND SSP1-RCP1.9'!G4/O$14*O$13 -> 0 | H4: ='REMIND SSP1-RCP1.9'!H4/P$14*P$13 -> 0 | J4: Roadmap-30-Bio | K4: =C25/C9 -> 0.81935946 | L4: =D25/D9 -> 2.6858642 | M4: =E25/E9 -> 10.486867 | N4: =F25/F9 -> 11.638142 | O4: =G25/G9 -> 10.757309 | P4: =H25/H9 -> 2.1591803
B5: atj | C5: ='REMIND SSP1-RCP1.9'!C5/K$14*K$13 -> 0 | D5: ='REMIND SSP1-RCP1.9'!D5/L$14*L$13 -> 0 | E5: ='REMIND SSP1-RCP1.9'!E5/M$14*M$13 -> 0 | F5: ='REMIND SSP1-RCP1.9'!F5/N$14*N$13 -> 0 | G5: ='REMIND SSP1-RCP1.9'!G5/O$14*O$13 -> 0 | H5: ='REMIND SSP1-RCP1.9'!H5/P$14*P$13 -> 0 | J5: Roadmap-0 | K5: =C33/C9 -> 0.69798199 | L5: =D33/D9 -> 2.3912899 | M5: =E33/E9 -> 18.553218 | N5: =F33/F9 -> 12.547109 | O5: =G33/G9 -> 20.487546 | P5: =H33/H9 -> 1.9477611
B6: ft | C6: ='REMIND SSP1-RCP1.9'!C6/K$14*K$13 -> 0 | D6: ='REMIND SSP1-RCP1.9'!D6/L$14*L$13 -> 0 | E6: ='REMIND SSP1-RCP1.9'!E6/M$14*M$13 -> 0 | F6: ='REMIND SSP1-RCP1.9'!F6/N$14*N$13 -> 0 | G6: ='REMIND SSP1-RCP1.9'!G6/O$14*O$13 -> 0 | H6: ='REMIND SSP1-RCP1.9'!H6/P$14*P$13 -> 0 | J6: Roadmap-30-Efuel | K6: =C41/C9 -> 0.82893611 | L6: =D41/D9 -> 2.1916883 | M6: =E41/E9 -> 12.508513 | N6: =F41/F9 -> 9.7121324 | O6: =G41/G9 -> 13.752444 | P6: =H41/H9 -> 1.7996734
B7: hefa | C7: ='REMIND SSP1-RCP1.9'!C7/K$14*K$13 -> 0 | D7: ='REMIND SSP1-RCP1.9'!D7/L$14*L$13 -> 0 | E7: ='REMIND SSP1-RCP1.9'!E7/M$14*M$13 -> 0 | F7: ='REMIND SSP1-RCP1.9'!F7/N$14*N$13 -> 0 | G7: ='REMIND SSP1-RCP1.9'!G7/O$14*O$13 -> 0 | H7: ='REMIND SSP1-RCP1.9'!H7/P$14*P$13 -> 0 | J7: Bio-Adv | K7: =C49/C9 -> 0.64814549 | L7: =D49/D9 -> 3.9450515 | M7: =E49/E9 -> 10.483932 | N7: =F49/F9 -> 18.27791 | O7: =G49/G9 -> 9.3032742 | P7: =H49/H9 -> 3.1197584
B8: lh2 | C8: ='REMIND SSP1-RCP1.9'!C8/K$14*K$13 -> 0 | D8: ='REMIND SSP1-RCP1.9'!D8/L$14*L$13 -> 0 | E8: ='REMIND SSP1-RCP1.9'!E8/M$14*M$13 -> 0 | F8: ='REMIND SSP1-RCP1.9'!F8/N$14*N$13 -> 0 | G8: ='REMIND SSP1-RCP1.9'!G8/O$14*O$13 -> 0 | H8: ='REMIND SSP1-RCP1.9'!H8/P$14*P$13 -> 0 | J8: Bio-HEFA | K8: =C57/C9 -> 0.66668641 | L8: =D57/D9 -> 1.9524172 | M8: =E57/E9 -> 29.56417 | N8: =F57/F9 -> 35.879314 | O8: =G57/G9 -> 12.489679 | P8: =H57/H9 -> 6.1275821
B9: total | C9: ='REMIND SSP1-RCP1.9'!C9/K$14*K$13 -> 2.5407749 | D9: ='REMIND SSP1-RCP1.9'!D9/L$14*L$13 -> 1.3163161 | E9: ='REMIND SSP1-RCP1.9'!E9/M$14*M$13 -> 0.035771037 | F9: ='REMIND SSP1-RCP1.9'!F9/N$14*N$13 -> 0.0021431362 | G9: ='REMIND SSP1-RCP1.9'!G9/O$14*O$13 -> 0.017561993 | H9: ='REMIND SSP1-RCP1.9'!H9/P$14*P$13 -> 0.010575417 | J9: Efuel-grid | K9: =C65/C9 -> 0.75916995 | L9: =D65/D9 -> 1.3217909 | M9: =E65/E9 -> 24.083901 | N9: =F65/F9 -> 8.3764718 | O9: =G65/G9 -> 28.784747 | P9: =H65/H9 -> 1.1432299
A10: Roadmap-70 | B10: fk_historical | C10: ='REMIND SSP1-RCP1.9'!C10/K$14*K$13 -> 1.033283 | D10: ='REMIND SSP1-RCP1.9'!D10/L$14*L$13 -> 0.52009974 | E10: ='REMIND SSP1-RCP1.9'!E10/M$14*M$13 -> 0 | F10: ='REMIND SSP1-RCP1.9'!F10/N$14*N$13 -> 0 | G10: ='REMIND SSP1-RCP1.9'!G10/O$14*O$13 -> 0 | H10: ='REMIND SSP1-RCP1.9'!H10/P$14*P$13 -> 0 | J10: Efuel-RES | K10: =C73/C9 -> 0.69473498 | L10: =D73/D9 -> 1.0799776 | M10: =E73/E9 -> 26.958228 | N10: =F73/F9 -> 11.269902 | O10: =G73/G9 -> 8.023143 | P10: =H73/H9 -> 1.1461358
B11: fk | C11: ='REMIND SSP1-RCP1.9'!C11/K$14*K$13 -> 1.3850757 | D11: ='REMIND SSP1-RCP1.9'!D11/L$14*L$13 -> 0.72450128 | E11: ='REMIND SSP1-RCP1.9'!E11/M$14*M$13 -> 0.02611999 | F11: ='REMIND SSP1-RCP1.9'!F11/N$14*N$13 -> 0.0015649168 | G11: ='REMIND SSP1-RCP1.9'!G11/O$14*O$13 -> 0.012823757 | H11: ='REMIND SSP1-RCP1.9'!H11/P$14*P$13 -> 0.0077221631
B12: efuels | C12: ='REMIND SSP1-RCP1.9'!C12/K$14*K$13 -> 0.033233314 | D12: ='REMIND SSP1-RCP1.9'!D12/L$14*L$13 -> 0.08220511 | E12: ='REMIND SSP1-RCP1.9'!E12/M$14*M$13 -> 0.073358835 | F12: ='REMIND SSP1-RCP1.9'!F12/N$14*N$13 -> 0.0015275034 | G12: ='REMIND SSP1-RCP1.9'!G12/O$14*O$13 -> 0.043048536 | H12: ='REMIND SSP1-RCP1.9'!H12/P$14*P$13 -> 0.0010213122 | J12: shares | K12: CC | L12: BI | M12: N | N12: P | O12: SOD | P12: FWU
B13: atj | C13: ='REMIND SSP1-RCP1.9'!C13/K$14*K$13 -> 0.079026042 | D13: ='REMIND SSP1-RCP1.9'!D13/L$14*L$13 -> 0.40419792 | E13: ='REMIND SSP1-RCP1.9'!E13/M$14*M$13 -> 0.01594341 | F13: ='REMIND SSP1-RCP1.9'!F13/N$14*N$13 -> 0.0021287995 | G13: ='REMIND SSP1-RCP1.9'!G13/O$14*O$13 -> 0.010141196 | H13: ='REMIND SSP1-RCP1.9'!H13/P$14*P$13 -> 0.0019132621 | J13: FHN | K13: 0.9 | L13: 0.012 | M13: 0.02 | N13: 0.002 | O13: 2.2 | P13: 0.4
B14: ft | C14: ='REMIND SSP1-RCP1.9'!C14/K$14*K$13 -> -0.075097065 | D14: ='REMIND SSP1-RCP1.9'!D14/L$14*L$13 -> 0.40703908 | E14: ='REMIND SSP1-RCP1.9'!E14/M$14*M$13 -> 0.0140589 | F14: ='REMIND SSP1-RCP1.9'!F14/N$14*N$13 -> 0.0024643226 | G14: ='REMIND SSP1-RCP1.9'!G14/O$14*O$13 -> 0.013403038 | H14: ='REMIND SSP1-RCP1.9'!H14/P$14*P$13 -> 0.001940371 | J14: GDP | K14: 2.9 | L14: 2.9 | M14: 2.9 | N14: 2.9 | O14: 2.9 | P14: 2.9
